Workbook

Sheet Start Here
B2: Debt Freedom Planner
B3: Budget · Debt Payoff (Snowball or Avalanche) · Savings Goals
B5: HOW TO USE
B6: 1. Only edit the YELLOW cells. Everything else calculates automatically.
B7: 2. Monthly Budget: enter your take-home income and planned vs. actual spending.
B8: 3. Debt Payoff: list up to 8 debts, choose Snowball or Avalanche, and add any extra monthly payment.
B9: The sheet tells you your debt-free date, total interest, and when each debt is paid off.
B10: 4. Savings Goals: enter each goal, what you've saved, and your monthly contribution.
B11: 5. The example values are there to show the format. Overwrite them with your own numbers.
B13: SNOWBALL vs. AVALANCHE
B14: Snowball pays the smallest balance first. Quick wins keep you motivated.
B15: Avalanche pays the highest interest rate first. It costs the least in total interest.
... B26: Example cell to edit

Sheet Monthly Budget
B2: Monthly Budget
B4: Income | C4: Planned | D4: Actual | E4: Difference | G4: This month at a glance
B5: Paycheck 1 | C5: 2100 | D5: 2100 | E5: =D5-C5 -> 0 | G5: Income (actual) | H5: =D9 -> 4440
B6: Paycheck 2 | C6: 2100 | D6: 2100 | E6: =D6-C6 -> 0 | G6: Spending (actual) | H6: =D26 -> 4167
B7: Side income | C7: 300 | D7: 240 | E7: =D7-C7 -> -60 | G7: Left over | H7: =D9-D26 -> 273
B8: Other | C8: 0 | D8: 0 | E8: =D8-C8 -> 0 | G8: Savings rate | H8: =IFERROR('Savings Goals'!E15/D9,0) -> 0.078828829
B9: Total income | C9: =SUM(C5:C8) -> 4500 | D9: =SUM(D5:D8) -> 4440 | E9: =D9-C9 -> -60 | G9: Unassigned (planned) | H9: =C9-C26 -> 420
B11: Expense | C11: Planned | D11: Actual | E11: Left / (Over) | G11: Tip: aim for 'Unassigned (planned)' = $0. Give every dollar a job.
B12: Rent / Mortgage | C12: 1400 | D12: 1400 | E12: =C12-D12 -> 0
B13: Utilities | C13: 180 | D13: 195 | E13: =C13-D13 -> -15
B14: Groceries | C14: 450 | D14: 510 | E14: =C14-D14 -> -60
B15: Transportation | C15: 250 | D15: 230 | E15: =C15-D15 -> 20
B16: Insurance | C16: 160 | D16: 160 | E16: =C16-D16 -> 0
B17: Phone / Internet | C17: 110 | D17: 110 | E17: =C17-D17 -> 0
B18: Subscriptions | C18: 45 | D18: 62 | E18: =C18-D18 -> -17
B19: Dining out | C19: 150 | D19: 210 | E19: =C19-D19 -> -60
B20: Personal / Fun | C20: 120 | D20: 95 | E20: =C20-D20 -> 25
B21: Health | C21: 60 | D21: 40 | E21: =C21-D21 -> 20
B22: Debt payments | C22: ='Debt Payoff'!D17 -> 805 | D22: ='Debt Payoff'!D17 -> 805 | E22: =C22-D22 -> 0
B23: Savings | C23: ='Savings Goals'!E15 -> 350 | D23: ='Savings Goals'!E15 -> 350 | E23: =C23-D23 -> 0
B24: Other | C24: 0 | D24: 0 | E24: =C24-D24 -> 0
B25: Other | C25: 0 | D25: 0 | E25: =C25-D25 -> 0
B26: Total expenses | C26: =SUM(C12:C25) -> 4080 | D26: =SUM(D12:D25) -> 4167 | E26: =C26-D26 -> -87

Sheet Debt Payoff
B2: Debt Payoff Planner
B4: Payoff method | C4: Avalanche | D4: ← pick from list
B5: Extra payment / month | C5: 200 | D5: ← on top of all minimum payments
B6: Start month | C6: 46327
B8: Debt name | C8: Balance | D8: APR | E8: Min payment | F8: Pay order | H8: Paid off in (months) | I8: Paid off | J8: Interest paid
B9: Credit card A | C9: 4200 | D9: 0.2449 | E9: 120 | F9: =IF(N(C9)<=0,"",COUNTIF($L$9:$L$16,"<"&L9)+1) -> 1 | H9: =IF(N(C9)<=0,"",IF(INDEX(Calc!AY:AY,363)>0.005,"30+ yrs",COUNTIF(Calc!AY3:AY362,">0.005")+1)) -> 16 | I9: =IF(N(C9)<=0,"",IF(ISNUMBER(H9),EDATE($C$6,H9-1),"—")) -> 46784 | J9: =IF(N(C9)<=0,"",SUM(Calc!J3:J362)) -> 739.22412 | L9: =IF(N(C9)<=0,1000000000000,IF($C$4="Snowball",C9,-D9))+ROW()/1000000000 -> -0.24489999
B10: Credit card B | C10: 1350 | D10: 0.1999 | E10: 40 | F10: =IF(N(C10)<=0,"",COUNTIF($L$9:$L$16,"<"&L10)+1) -> 2 | H10: =IF(N(C10)<=0,"",IF(INDEX(Calc!AZ:AZ,363)>0.005,"30+ yrs",COUNTIF(Calc!AZ3:AZ362,">0.005")+1)) -> 19 | I10: =IF(N(C10)<=0,"",IF(ISNUMBER(H10),EDATE($C$6,H10-1),"—")) -> 46874 | J10: =IF(N(C10)<=0,"",SUM(Calc!K3:K362)) -> 347.09753 | L10: =IF(N(C10)<=0,1000000000000,IF($C$4="Snowball",C10,-D10))+ROW()/1000000000 -> -0.19989999
B11: Car loan | C11: 9800 | D11: 0.069 | E11: 285 | F11: =IF(N(C11)<=0,"",COUNTIF($L$9:$L$16,"<"&L11)+1) -> 3 | H11: =IF(N(C11)<=0,"",IF(INDEX(Calc!BA:BA,363)>0.005,"30+ yrs",COUNTIF(Calc!BA3:BA362,">0.005")+1)) -> 27 | I11: =IF(N(C11)<=0,"",IF(ISNUMBER(H11),EDATE($C$6,H11-1),"—")) -> 47119 | J11: =IF(N(C11)<=0,"",SUM(Calc!L3:L362)) -> 968.89087 | L11: =IF(N(C11)<=0,1000000000000,IF($C$4="Snowball",C11,-D11))+ROW()/1000000000 -> -0.068999989
B12: Student loan | C12: 14500 | D12: 0.055 | E12: 160 | F12: =IF(N(C12)<=0,"",COUNTIF($L$9:$L$16,"<"&L12)+1) -> 4 | H12: =IF(N(C12)<=0,"",IF(INDEX(Calc!BB:BB,363)>0.005,"30+ yrs",COUNTIF(Calc!BB3:BB362,">0.005")+1)) -> 43 | I12: =IF(N(C12)<=0,"",IF(ISNUMBER(H12),EDATE($C$6,H12-1),"—")) -> 47604 | J12: =IF(N(C12)<=0,"",SUM(Calc!M3:M362)) -> 2081.9657 | L12: =IF(N(C12)<=0,1000000000000,IF($C$4="Snowball",C12,-D12))+ROW()/1000000000 -> -0.054999988
C13: 0 | D13: 0 | E13: 0 | F13: =IF(N(C13)<=0,"",COUNTIF($L$9:$L$16,"<"&L13)+1) | H13: =IF(N(C13)<=0,"",IF(INDEX(Calc!BC:BC,363)>0.005,"30+ yrs",COUNTIF(Calc!BC3:BC362,">0.005")+1)) | I13: =IF(N(C13)<=0,"",IF(ISNUMBER(H13),EDATE($C$6,H13-1),"—")) | J13: =IF(N(C13)<=0,"",SUM(Calc!N3:N362)) | L13: =IF(N(C13)<=0,1000000000000,IF($C$4="Snowball",C13,-D13))+ROW()/1000000000 -> 1000000000000
C14: 0 | D14: 0 | E14: 0 | F14: =IF(N(C14)<=0,"",COUNTIF($L$9:$L$16,"<"&L14)+1) | H14: =IF(N(C14)<=0,"",IF(INDEX(Calc!BD:BD,363)>0.005,"30+ yrs",COUNTIF(Calc!BD3:BD362,">0.005")+1)) | I14: =IF(N(C14)<=0,"",IF(ISNUMBER(H14),EDATE($C$6,H14-1),"—")) | J14: =IF(N(C14)<=0,"",SUM(Calc!O3:O362)) | L14: =IF(N(C14)<=0,1000000000000,IF($C$4="Snowball",C14,-D14))+ROW()/1000000000 -> 1000000000000
C15: 0 | D15: 0 | E15: 0 | F15: =IF(N(C15)<=0,"",COUNTIF($L$9:$L$16,"<"&L15)+1) | H15: =IF(N(C15)<=0,"",IF(INDEX(Calc!BE:BE,363)>0.005,"30+ yrs",COUNTIF(Calc!BE3:BE362,">0.005")+1)) | I15: =IF(N(C15)<=0,"",IF(ISNUMBER(H15),EDATE($C$6,H15-1),"—")) | J15: =IF(N(C15)<=0,"",SUM(Calc!P3:P362)) | L15: =IF(N(C15)<=0,1000000000000,IF($C$4="Snowball",C15,-D15))+ROW()/1000000000 -> 1000000000000
C16: 0 | D16: 0 | E16: 0 | F16: =IF(N(C16)<=0,"",COUNTIF($L$9:$L$16,"<"&L16)+1) | H16: =IF(N(C16)<=0,"",IF(INDEX(Calc!BF:BF,363)>0.005,"30+ yrs",COUNTIF(Calc!BF3:BF362,">0.005")+1)) | I16: =IF(N(C16)<=0,"",IF(ISNUMBER(H16),EDATE($C$6,H16-1),"—")) | J16: =IF(N(C16)<=0,"",SUM(Calc!Q3:Q362)) | L16: =IF(N(C16)<=0,1000000000000,IF($C$4="Snowball",C16,-D16))+ROW()/1000000000 -> 1000000000000
B17: Totals | C17: =SUM(C9:C16) -> 29850 | D17: =SUM(E9:E16)+C5 -> 805 | E17: ← total paid / month | J17: =SUM(J9:J16) -> 4137.1782
B19: Your results
B20: Debt-free date | C20: =IF(Calc!BG362>0.005,"Over 30 years: raise your payment",EDATE(C6,COUNTIF(Calc!BG3:BG362,">0.005"))) -> 47604
B21: Months to debt-free | C21: =IF(Calc!BG362>0.005,"360+",COUNTIF(Calc!BG3:BG362,">0.005")+1) -> 43
B22: Total interest you'll pay | C22: =J17 -> 4137.1782
B23: Paid first | C23: =IFERROR(INDEX(B9:B16,MATCH(1,F9:F16,0)),"") -> Credit card A
B25: Rows highlighted green are the debt to attack first. Try switching the method and changing the extra payment to see how your date moves.
B26: If a minimum payment doesn't cover the monthly interest, that debt will never shrink. Check 'Paid off in' for '30+ yrs'.

Sheet Calc
A1: Month-by-month engine for the Debt Payoff tab. Don't edit. | AH1: =IF('Debt Payoff'!F9="",99,'Debt Payoff'!F9) -> 1 | AI1: =IF('Debt Payoff'!F10="",99,'Debt Payoff'!F10) -> 2 | AJ1: =IF('Debt Payoff'!F11="",99,'Debt Payoff'!F11) -> 3 | AK1: =IF('Debt Payoff'!F12="",99,'Debt Payoff'!F12) -> 4 | AL1: =IF('Debt Payoff'!F13="",99,'Debt Payoff'!F13) -> 99 | AM1: =IF('Debt Payoff'!F14="",99,'Debt Payoff'!F14) -> 99 | AN1: =IF('Debt Payoff'!F15="",99,'Debt Payoff'!F15) -> 99 | AO1: =IF('Debt Payoff'!F16="",99,'Debt Payoff'!F16) -> 99
A2: Month | B2: Start 1 | C2: Start 2 | D2: Start 3 | E2: Start 4 | F2: Start 5 | G2: Start 6 | H2: Start 7 | I2: Start 8 | J2: Interest 1 | K2: Interest 2 | L2: Interest 3 | M2: Interest 4 | N2: Interest 5 | O2: Interest 6 | P2: Interest 7 | Q2: Interest 8 | R2: Owed 1 | S2: Owed 2 | T2: Owed 3 | U2: Owed 4 | V2: Owed 5 | W2: Owed 6 | X2: Owed 7 | Y2: Owed 8 | Z2: MinPay 1 | AA2: MinPay 2 | AB2: MinPay 3 | AC2: MinPay 4 | AD2: MinPay 5 | AE2: MinPay 6 | AF2: MinPay 7 | AG2: MinPay 8 | AH2: Remain 1 | AI2: Remain 2 | AJ2: Remain 3 | AK2: Remain 4 | AL2: Remain 5 | AM2: Remain 6 | AN2: Remain 7 | AO2: Remain 8 | AP2: Pool | AQ2: Extra 1 | AR2: Extra 2 | AS2: Extra 3 | AT2: Extra 4 | AU2: Extra 5 | AV2: Extra 6 | AW2: Extra 7 | AX2: Extra 8 | AY2: End 1 | AZ2: End 2 | BA2: End 3 | BB2: End 4 | BC2: End 5 | BD2: End 6 | BE2: End 7 | BF2: End 8 | BG2: Total end bal
A3: 1 | B3: =N('Debt Payoff'!C9) -> 4200 | C3: =N('Debt Payoff'!C10) -> 1350 | D3: =N('Debt Payoff'!C11) -> 9800 | E3: =N('Debt Payoff'!C12) -> 14500 | F3: =N('Debt Payoff'!C13) -> 0 | G3: =N('Debt Payoff'!C14) -> 0 | H3: =N('Debt Payoff'!C15) -> 0 | I3: =N('Debt Payoff'!C16) -> 0 | J3: =B3*N('Debt Payoff'!D9)/12 -> 85.715 | K3: =C3*N('Debt Payoff'!D10)/12 -> 22.48875 | L3: =D3*N('Debt Payoff'!D11)/12 -> 56.35 | M3: =E3*N('Debt Payoff'!D12)/12 -> 66.458333 | N3: =F3*N('Debt Payoff'!D13)/12 -> 0 | O3: =G3*N('Debt Payoff'!D14)/12 -> 0 | P3: =H3*N('Debt Payoff'!D15)/12 -> 0 | Q3: =I3*N('Debt Payoff'!D16)/12 -> 0 | R3: =B3+J3 -> 4285.715 | S3: =C3+K3 -> 1372.4887 | T3: =D3+L3 -> 9856.35 | U3: =E3+M3 -> 14566.458 | V3: =F3+N3 -> 0 | W3: =G3+O3 -> 0 | X3: =H3+P3 -> 0 | Y3: =I3+Q3 -> 0 | Z3: =MIN(R3,N('Debt Payoff'!E9)) -> 120 | AA3: =MIN(S3,N('Debt Payoff'!E10)) -> 40 | AB3: =MIN(T3,N('Debt Payoff'!E11)) -> 285 | AC3: =MIN(U3,N('Debt Payoff'!E12)) -> 160 | AD3: =MIN(V3,N('Debt Payoff'!E13)) -> 0 | AE3: =MIN(W3,N('Debt Payoff'!E14)) -> 0 | AF3: =MIN(X3,N('Debt Payoff'!E15)) -> 0 | AG3: =MIN(Y3,N('Debt Payoff'!E16)) -> 0 | AH3: =R3-Z3 -> 4165.715 | AI3: =S3-AA3 -> 1332.4887 | AJ3: =T3-AB3 -> 9571.35 | AK3: =U3-AC3 -> 14406.458 | AL3: =V3-AD3 -> 0 | AM3: =W3-AE3 -> 0 | AN3: =X3-AF3 -> 0 | AO3: =Y3-AG3 -> 0 | AP3: =MAX(0,'Debt Payoff'!$D$17-SUM(Z3:AG3)) -> 200 | AQ3: =MIN(AH3,MAX(0,$AP3-SUMPRODUCT(($AH$1:$AO$1<AH$1)*$AH3:$AO3))) -> 200 | AR3: =MIN(AI3,MAX(0,$AP3-SUMPRODUCT(($AH$1:$AO$1<AI$1)*$AH3:$AO3))) -> 0 | AS3: =MIN(AJ3,MAX(0,$AP3-SUMPRODUCT(($AH$1:$AO$1<AJ$1)*$AH3:$AO3))) -> 0 | AT3: =MIN(AK3,MAX(0,$AP3-SUMPRODUCT(($AH$1:$AO$1<AK$1)*$AH3:$AO3))) -> 0 | AU3: =MIN(AL3,MAX(0,$AP3-SUMPRODUCT(($AH$1:$AO$1<AL$1)*$AH3:$AO3))) -> 0 | AV3: =MIN(AM3,MAX(0,$AP3-SUMPRODUCT(($AH$1:$AO$1<AM$1)*$AH3:$AO3))) -> 0 | AW3: =MIN(AN3,MAX(0,$AP3-SUMPRODUCT(($AH$1:$AO$1<AN$1)*$AH3:$AO3))) -> 0 | AX3: =MIN(AO3,MAX(0,$AP3-SUMPRODUCT(($AH$1:$AO$1<AO$1)*$AH3:$AO3))) -> 0 | AY3: =ROUND(AH3-AQ3,2) -> 3965.72 | AZ3: =ROUND(AI3-AR3,2) -> 1332.49 | BA3: =ROUND(AJ3-AS3,2) -> 9571.35 | BB3: =ROUND(AK3-AT3,2) -> 14406.46 | BC3: =ROUND(AL3-AU3,2) -> 0 | BD3: =ROUND(AM3-AV3,2) -> 0 | BE3: =ROUND(AN3-AW3,2) -> 0 | BF3: =ROUND(AO3-AX3,2) -> 0 | BG3: =SUM(AY3:BF3) -> 29276.02
A4: 2 | B4: =AY3 -> 3965.72 | C4: =AZ3 -> 1332.49 | D4: =BA3 -> 9571.35 | E4: =BB3 -> 14406.46 | F4: =BC3 -> 0 | G4: =BD3 -> 0 | H4: =BE3 -> 0 | I4: =BF3 -> 0 | J4: =B4*N('Debt Payoff'!D9)/12 -> 80.933736 | K4: =C4*N('Debt Payoff'!D10)/12 -> 22.197063 | L4: =D4*N('Debt Payoff'!D11)/12 -> 55.035263 | M4: =E4*N('Debt Payoff'!D12)/12 -> 66.029608 | N4: =F4*N('Debt Payoff'!D13)/12 -> 0 | O4: =G4*N('Debt Payoff'!D14)/12 -> 0 | P4: =H4*N('Debt Payoff'!D15)/12 -> 0 | Q4: =I4*N('Debt Payoff'!D16)/12 -> 0 | R4: =B4+J4 -> 4046.6537 | S4: =C4+K4 -> 1354.6871 | T4: =D4+L4 -> 9626.3853 | U4: =E4+M4 -> 14472.49 | V4: =F4+N4 -> 0 | W4: =G4+O4 -> 0 | X4: =H4+P4 -> 0 | Y4: =I4+Q4 -> 0 | Z4: =MIN(R4,N('Debt Payoff'!E9)) -> 120 | AA4: =MIN(S4,N('Debt Payoff'!E10)) -> 40 | AB4: =MIN(T4,N('Debt Payoff'!E11)) -> 285 | AC4: =MIN(U4,N('Debt Payoff'!E12)) -> 160 | AD4: =MIN(V4,N('Debt Payoff'!E13)) -> 0 | AE4: =MIN(W4,N('Debt Payoff'!E14)) -> 0 | AF4: =MIN(X4,N('Debt Payoff'!E15)) -> 0 | AG4: =MIN(Y4,N('Debt Payoff'!E16)) -> 0 | AH4: =R4-Z4 -> 3926.6537 | AI4: =S4-AA4 -> 1314.6871 | AJ4: =T4-AB4 -> 9341.3853 | AK4: =U4-AC4 -> 14312.49 | AL4: =V4-AD4 -> 0 | AM4: =W4-AE4 -> 0 | AN4: =X4-AF4 -> 0 | AO4: =Y4-AG4 -> 0 | AP4: =MAX(0,'Debt Payoff'!$D$17-SUM(Z4:AG4)) -> 200 | AQ4: =MIN(AH4,MAX(0,$AP4-SUMPRODUCT(($AH$1:$AO$1<AH$1)*$AH4:$AO4))) -> 200 | AR4: =MIN(AI4,MAX(0,$AP4-SUMPRODUCT(($AH$1:$AO$1<AI$1)*$AH4:$AO4))) -> 0 | AS4: =MIN(AJ4,MAX(0,$AP4-SUMPRODUCT(($AH$1:$AO$1<AJ$1)*$AH4:$AO4))) -> 0 | AT4: =MIN(AK4,MAX(0,$AP4-SUMPRODUCT(($AH$1:$AO$1<AK$1)*$AH4:$AO4))) -> 0 | AU4: =MIN(AL4,MAX(0,$AP4-SUMPRODUCT(($AH$1:$AO$1<AL$1)*$AH4:$AO4))) -> 0 | AV4: =MIN(AM4,MAX(0,$AP4-SUMPRODUCT(($AH$1:$AO$1<AM$1)*$AH4:$AO4))) -> 0 | AW4: =MIN(AN4,MAX(0,$AP4-SUMPRODUCT(($AH$1:$AO$1<AN$1)*$AH4:$AO4))) -> 0 | AX4: =MIN(AO4,MAX(0,$AP4-SUMPRODUCT(($AH$1:$AO$1<AO$1)*$AH4:$AO4))) -> 0 | AY4: =ROUND(AH4-AQ4,2) -> 3726.65 | AZ4: =ROUND(AI4-AR4,2) -> 1314.69 | BA4: =ROUND(AJ4-AS4,2) -> 9341.39 | BB4: =ROUND(AK4-AT4,2) -> 14312.49 | BC4: =ROUND(AL4-AU4,2) -> 0 | BD4: =ROUND(AM4-AV4,2) -> 0 | BE4: =ROUND(AN4-AW4,2) -> 0 | BF4: =ROUND(AO4-AX4,2) -> 0 | BG4: =SUM(AY4:BF4) -> 28695.22
A5: 3 | B5: =AY4 -> 3726.65 | C5: =AZ4 -> 1314.69 | D5: =BA4 -> 9341.39 | E5: =BB4 -> 14312.49 | F5: =BC4 -> 0 | G5: =BD4 -> 0 | H5: =BE4 -> 0 | I5: =BF4 -> 0 | J5: =B5*N('Debt Payoff'!D9)/12 -> 76.054715 | K5: =C5*N('Debt Payoff'!D10)/12 -> 21.900544 | L5: =D5*N('Debt Payoff'!D11)/12 -> 53.712992 | M5: =E5*N('Debt Payoff'!D12)/12 -> 65.598912 | N5: =F5*N('Debt Payoff'!D13)/12 -> 0 | O5: =G5*N('Debt Payoff'!D14)/12 -> 0 | P5: =H5*N('Debt Payoff'!D15)/12 -> 0 | Q5: =I5*N('Debt Payoff'!D16)/12 -> 0 | R5: =B5+J5 -> 3802.7047 | S5: =C5+K5 -> 1336.5905 | T5: =D5+L5 -> 9395.103 | U5: =E5+M5 -> 14378.089 | V5: =F5+N5 -> 0 | W5: =G5+O5 -> 0 | X5: =H5+P5 -> 0 | Y5: =I5+Q5 -> 0 | Z5: =MIN(R5,N('Debt Payoff'!E9)) -> 120 | AA5: =MIN(S5,N('Debt Payoff'!E10)) -> 40 | AB5: =MIN(T5,N('Debt Payoff'!E11)) -> 285 | AC5: =MIN(U5,N('Debt Payoff'!E12)) -> 160 | AD5: =MIN(V5,N('Debt Payoff'!E13)) -> 0 | AE5: =MIN(W5,N('Debt Payoff'!E14)) -> 0 | AF5: =MIN(X5,N('Debt Payoff'!E15)) -> 0 | AG5: =MIN(Y5,N('Debt Payoff'!E16)) -> 0 | AH5: =R5-Z5 -> 3682.7047 | AI5: =S5-AA5 -> 1296.5905 | AJ5: =T5-AB5 -> 9110.103 | AK5: =U5-AC5 -> 14218.089 | AL5: =V5-AD5 -> 0 | AM5: =W5-AE5 -> 0 | AN5: =X5-AF5 -> 0 | AO5: =Y5-AG5 -> 0 | AP5: =MAX(0,'Debt Payoff'!$D$17-SUM(Z5:AG5)) -> 200 | AQ5: =MIN(AH5,MAX(0,$AP5-SUMPRODUCT(($AH$1:$AO$1<AH$1)*$AH5:$AO5))) -> 200 | AR5: =MIN(AI5,MAX(0,$AP5-SUMPRODUCT(($AH$1:$AO$1<AI$1)*$AH5:$AO5))) -> 0 | AS5: =MIN(AJ5,MAX(0,$AP5-SUMPRODUCT(($AH$1:$AO$1<AJ$1)*$AH5:$AO5))) -> 0 | AT5: =MIN(AK5,MAX(0,$AP5-SUMPRODUCT(($AH$1:$AO$1<AK$1)*$AH5:$AO5))) -> 0 | AU5: =MIN(AL5,MAX(0,$AP5-SUMPRODUCT(($AH$1:$AO$1<AL$1)*$AH5:$AO5))) -> 0 | AV5: =MIN(AM5,MAX(0,$AP5-SUMPRODUCT(($AH$1:$AO$1<AM$1)*$AH5:$AO5))) -> 0 | AW5: =MIN(AN5,MAX(0,$AP5-SUMPRODUCT(($AH$1:$AO$1<AN$1)*$AH5:$AO5))) -> 0 | AX5: =MIN(AO5,MAX(0,$AP5-SUMPRODUCT(($AH$1:$AO$1<AO$1)*$AH5:$AO5))) -> 0 | AY5: =ROUND(AH5-AQ5,2) -> 3482.7 | AZ5: =ROUND(AI5-AR5,2) -> 1296.59 | BA5: =ROUND(AJ5-AS5,2) -> 9110.1 | BB5: =ROUND(AK5-AT5,2) -> 14218.09 | BC5: =ROUND(AL5-AU5,2) -> 0 | BD5: =ROUND(AM5-AV5,2) -> 0 | BE5: =ROUND(AN5-AW5,2) -> 0 | BF5: =ROUND(AO5-AX5,2) -> 0 | BG5: =SUM(AY5:BF5) -> 28107.48
A6: 4 | B6: =AY5 -> 3482.7 | C6: =AZ5 -> 1296.59 | D6: =BA5 -> 9110.1 | E6: =BB5 -> 14218.09 | F6: =BC5 -> 0 | G6: =BD5 -> 0 | H6: =BE5 -> 0 | I6: =BF5 -> 0 | J6: =B6*N('Debt Payoff'!D9)/12 -> 71.076103 | K6: =C6*N('Debt Payoff'!D10)/12 -> 21.599028 | L6: =D6*N('Debt Payoff'!D11)/12 -> 52.383075 | M6: =E6*N('Debt Payoff'!D12)/12 -> 65.166246 | N6: =F6*N('Debt Payoff'!D13)/12 -> 0 | O6: =G6*N('Debt Payoff'!D14)/12 -> 0 | P6: =H6*N('Debt Payoff'!D15)/12 -> 0 | Q6: =I6*N('Debt Payoff'!D16)/12 -> 0 | R6: =B6+J6 -> 3553.7761 | S6: =C6+K6 -> 1318.189 | T6: =D6+L6 -> 9162.4831 | U6: =E6+M6 -> 14283.256 | V6: =F6+N6 -> 0 | W6: =G6+O6 -> 0 | X6: =H6+P6 -> 0 | Y6: =I6+Q6 -> 0 | Z6: =MIN(R6,N('Debt Payoff'!E9)) -> 120 | AA6: =MIN(S6,N('Debt Payoff'!E10)) -> 40 | AB6: =MIN(T6,N('Debt Payoff'!E11)) -> 285 | AC6: =MIN(U6,N('Debt Payoff'!E12)) -> 160 | AD6: =MIN(V6,N('Debt Payoff'!E13)) -> 0 | AE6: =MIN(W6,N('Debt Payoff'!E14)) -> 0 | AF6: =MIN(X6,N('Debt Payoff'!E15)) -> 0 | AG6: =MIN(Y6,N('Debt Payoff'!E16)) -> 0 | AH6: =R6-Z6 -> 3433.7761 | AI6: =S6-AA6 -> 1278.189 | AJ6: =T6-AB6 -> 8877.4831 | AK6: =U6-AC6 -> 14123.256 | AL6: =V6-AD6 -> 0 | AM6: =W6-AE6 -> 0 | AN6: =X6-AF6 -> 0 | AO6: =Y6-AG6 -> 0 | AP6: =MAX(0,'Debt Payoff'!$D$17-SUM(Z6:AG6)) -> 200 | AQ6: =MIN(AH6,MAX(0,$AP6-SUMPRODUCT(($AH$1:$AO$1<AH$1)*$AH6:$AO6))) -> 200 | AR6: =MIN(AI6,MAX(0,$AP6-SUMPRODUCT(($AH$1:$AO$1<AI$1)*$AH6:$AO6))) -> 0 | AS6: =MIN(AJ6,MAX(0,$AP6-SUMPRODUCT(($AH$1:$AO$1<AJ$1)*$AH6:$AO6))) -> 0 | AT6: =MIN(AK6,MAX(0,$AP6-SUMPRODUCT(($AH$1:$AO$1<AK$1)*$AH6:$AO6))) -> 0 | AU6: =MIN(AL6,MAX(0,$AP6-SUMPRODUCT(($AH$1:$AO$1<AL$1)*$AH6:$AO6))) -> 0 | AV6: =MIN(AM6,MAX(0,$AP6-SUMPRODUCT(($AH$1:$AO$1<AM$1)*$AH6:$AO6))) -> 0 | AW6: =MIN(AN6,MAX(0,$AP6-SUMPRODUCT(($AH$1:$AO$1<AN$1)*$AH6:$AO6))) -> 0 | AX6: =MIN(AO6,MAX(0,$AP6-SUMPRODUCT(($AH$1:$AO$1<AO$1)*$AH6:$AO6))) -> 0 | AY6: =ROUND(AH6-AQ6,2) -> 3233.78 | AZ6: =ROUND(AI6-AR6,2) -> 1278.19 | BA6: =ROUND(AJ6-AS6,2) -> 8877.48 | BB6: =ROUND(AK6-AT6,2) -> 14123.26 | BC6: =ROUND(AL6-AU6,2) -> 0 | BD6: =ROUND(AM6-AV6,2) -> 0 | BE6: =ROUND(AN6-AW6,2) -> 0 | BF6: =ROUND(AO6-AX6,2) -> 0 | BG6: =SUM(AY6:BF6) -> 27512.71
A7: 5 | B7: =AY6 -> 3233.78 | C7: =AZ6 -> 1278.19 | D7: =BA6 -> 8877.48 | E7: =BB6 -> 14123.26 | F7: =BC6 -> 0 | G7: =BD6 -> 0 | H7: =BE6 -> 0 | I7: =BF6 -> 0 | J7: =B7*N('Debt Payoff'!D9)/12 -> 65.99606 | K7: =C7*N('Debt Payoff'!D10)/12 -> 21.292515 | L7: =D7*N('Debt Payoff'!D11)/12 -> 51.04551 | M7: =E7*N('Debt Payoff'!D12)/12 -> 64.731608 | N7: =F7*N('Debt Payoff'!D13)/12 -> 0 | O7: =G7*N('Debt Payoff'!D14)/12 -> 0 | P7: =H7*N('Debt Payoff'!D15)/12 -> 0 | Q7: =I7*N('Debt Payoff'!D16)/12 -> 0 | R7: =B7+J7 -> 3299.7761 | S7: =C7+K7 -> 1299.4825 | T7: =D7+L7 -> 8928.5255 | U7: =E7+M7 -> 14187.992 | V7: =F7+N7 -> 0 | W7: =G7+O7 -> 0 | X7: =H7+P7 -> 0 | Y7: =I7+Q7 -> 0 | Z7: =MIN(R7,N('Debt Payoff'!E9)) -> 120 | AA7: =MIN(S7,N('Debt Payoff'!E10)) -> 40 | AB7: =MIN(T7,N('Debt Payoff'!E11)) -> 285 | AC7: =MIN(U7,N('Debt Payoff'!E12)) -> 160 | AD7: =MIN(V7,N('Debt Payoff'!E13)) -> 0 | AE7: =MIN(W7,N('Debt Payoff'!E14)) -> 0 | AF7: =MIN(X7,N('Debt Payoff'!E15)) -> 0 | AG7: =MIN(Y7,N('Debt Payoff'!E16)) -> 0 | AH7: =R7-Z7 -> 3179.7761 | AI7: =S7-AA7 -> 1259.4825 | AJ7: =T7-AB7 -> 8643.5255 | AK7: =U7-AC7 -> 14027.992 | AL7: =V7-AD7 -> 0 | AM7: =W7-AE7 -> 0 | AN7: =X7-AF7 -> 0 | AO7: =Y7-AG7 -> 0 | AP7: =MAX(0,'Debt Payoff'!$D$17-SUM(Z7:AG7)) -> 200 | AQ7: =MIN(AH7,MAX(0,$AP7-SUMPRODUCT(($AH$1:$AO$1<AH$1)*$AH7:$AO7))) -> 200 | AR7: =MIN(AI7,MAX(0,$AP7-SUMPRODUCT(($AH$1:$AO$1<AI$1)*$AH7:$AO7))) -> 0 | AS7: =MIN(AJ7,MAX(0,$AP7-SUMPRODUCT(($AH$1:$AO$1<AJ$1)*$AH7:$AO7))) -> 0 | AT7: =MIN(AK7,MAX(0,$AP7-SUMPRODUCT(($AH$1:$AO$1<AK$1)*$AH7:$AO7))) -> 0 | AU7: =MIN(AL7,MAX(0,$AP7-SUMPRODUCT(($AH$1:$AO$1<AL$1)*$AH7:$AO7))) -> 0 | AV7: =MIN(AM7,MAX(0,$AP7-SUMPRODUCT(($AH$1:$AO$1<AM$1)*$AH7:$AO7))) -> 0 | AW7: =MIN(AN7,MAX(0,$AP7-SUMPRODUCT(($AH$1:$AO$1<AN$1)*$AH7:$AO7))) -> 0 | AX7: =MIN(AO7,MAX(0,$AP7-SUMPRODUCT(($AH$1:$AO$1<AO$1)*$AH7:$AO7))) -> 0 | AY7: =ROUND(AH7-AQ7,2) -> 2979.78 | AZ7: =ROUND(AI7-AR7,2) -> 1259.48 | BA7: =ROUND(AJ7-AS7,2) -> 8643.53 | BB7: =ROUND(AK7-AT7,2) -> 14027.99 | BC7: =ROUND(AL7-AU7,2) -> 0 | BD7: =ROUND(AM7-AV7,2) -> 0 | BE7: =ROUND(AN7-AW7,2) -> 0 | BF7: =ROUND(AO7-AX7,2) -> 0 | BG7: =SUM(AY7:BF7) -> 26910.78
A8: 6 | B8: =AY7 -> 2979.78 | C8: =AZ7 -> 1259.48 | D8: =BA7 -> 8643.53 | E8: =BB7 -> 14027.99 | F8: =BC7 -> 0 | G8: =BD7 -> 0 | H8: =BE7 -> 0 | I8: =BF7 -> 0 | J8: =B8*N('Debt Payoff'!D9)/12 -> 60.812343 | K8: =C8*N('Debt Payoff'!D10)/12 -> 20.980838 | L8: =D8*N('Debt Payoff'!D11)/12 -> 49.700297 | M8: =E8*N('Debt Payoff'!D12)/12 -> 64.294954 | N8: =F8*N('Debt Payoff'!D13)/12 -> 0 | O8: =G8*N('Debt Payoff'!D14)/12 -> 0 | P8: =H8*N('Debt Payoff'!D15)/12 -> 0 | Q8: =I8*N('Debt Payoff'!D16)/12 -> 0 | R8: =B8+J8 -> 3040.5923 | S8: =C8+K8 -> 1280.4608 | T8: =D8+L8 -> 8693.2303 | U8: =E8+M8 -> 14092.285 | V8: =F8+N8 -> 0 | W8: =G8+O8 -> 0 | X8: =H8+P8 -> 0 | Y8: =I8+Q8 -> 0 | Z8: =MIN(R8,N('Debt Payoff'!E9)) -> 120 | AA8: =MIN(S8,N('Debt Payoff'!E10)) -> 40 | AB8: =MIN(T8,N('Debt Payoff'!E11)) -> 285 | AC8: =MIN(U8,N('Debt Payoff'!E12)) -> 160 | AD8: =MIN(V8,N('Debt Payoff'!E13)) -> 0 | AE8: =MIN(W8,N('Debt Payoff'!E14)) -> 0 | AF8: =MIN(X8,N('Debt Payoff'!E15)) -> 0 | AG8: =MIN(Y8,N('Debt Payoff'!E16)) -> 0 | AH8: =R8-Z8 -> 2920.5923 | AI8: =S8-AA8 -> 1240.4608 | AJ8: =T8-AB8 -> 8408.2303 | AK8: =U8-AC8 -> 13932.285 | AL8: =V8-AD8 -> 0 | AM8: =W8-AE8 -> 0 | AN8: =X8-AF8 -> 0 | AO8: =Y8-AG8 -> 0 | AP8: =MAX(0,'Debt Payoff'!$D$17-SUM(Z8:AG8)) -> 200 | AQ8: =MIN(AH8,MAX(0,$AP8-SUMPRODUCT(($AH$1:$AO$1<AH$1)*$AH8:$AO8))) -> 200 | AR8: =MIN(AI8,MAX(0,$AP8-SUMPRODUCT(($AH$1:$AO$1<AI$1)*$AH8:$AO8))) -> 0 | AS8: =MIN(AJ8,MAX(0,$AP8-SUMPRODUCT(($AH$1:$AO$1<AJ$1)*$AH8:$AO8))) -> 0 | AT8: =MIN(AK8,MAX(0,$AP8-SUMPRODUCT(($AH$1:$AO$1<AK$1)*$AH8:$AO8))) -> 0 | AU8: =MIN(AL8,MAX(0,$AP8-SUMPRODUCT(($AH$1:$AO$1<AL$1)*$AH8:$AO8))) -> 0 | AV8: =MIN(AM8,MAX(0,$AP8-SUMPRODUCT(($AH$1:$AO$1<AM$1)*$AH8:$AO8))) -> 0 | AW8: =MIN(AN8,MAX(0,$AP8-SUMPRODUCT(($AH$1:$AO$1<AN$1)*$AH8:$AO8))) -> 0 | AX8: =MIN(AO8,MAX(0,$AP8-SUMPRODUCT(($AH$1:$AO$1<AO$1)*$AH8:$AO8))) -> 0 | AY8: =ROUND(AH8-AQ8,2) -> 2720.59 | AZ8: =ROUND(AI8-AR8,2) -> 1240.46 | BA8: =ROUND(AJ8-AS8,2) -> 8408.23 | BB8: =ROUND(AK8-AT8,2) -> 13932.28 | BC8: =ROUND(AL8-AU8,2) -> 0 | BD8: =ROUND(AM8-AV8,2) -> 0 | BE8: =ROUND(AN8-AW8,2) -> 0 | BF8: =ROUND(AO8-AX8,2) -> 0 | BG8: =SUM(AY8:BF8) -> 26301.56
A9: 7 | B9: =AY8 -> 2720.59 | C9: =AZ8 -> 1240.46 | D9: =BA8 -> 8408.23 | E9: =BB8 -> 13932.28 | F9: =BC8 -> 0 | G9: =BD8 -> 0 | H9: =BE8 -> 0 | I9: =BF8 -> 0 | J9: =B9*N('Debt Payoff'!D9)/12 -> 55.522708 | K9: =C9*N('Debt Payoff'!D10)/12 -> 20.663996 | L9: =D9*N('Debt Payoff'!D11)/12 -> 48.347322 | M9: =E9*N('Debt Payoff'!D12)/12 -> 63.856283 | N9: =F9*N('Debt Payoff'!D13)/12 -> 0 | O9: =G9*N('Debt Payoff'!D14)/12 -> 0 | P9: =H9*N('Debt Payoff'!D15)/12 -> 0 | Q9: =I9*N('Debt Payoff'!D16)/12 -> 0 | R9: =B9+J9 -> 2776.1127 | S9: =C9+K9 -> 1261.124 | T9: =D9+L9 -> 8456.5773 | U9: =E9+M9 -> 13996.136 | V9: =F9+N9 -> 0 | W9: =G9+O9 -> 0 | X9: =H9+P9 -> 0 | Y9: =I9+Q9 -> 0 | Z9: =MIN(R9,N('Debt Payoff'!E9)) -> 120 | AA9: =MIN(S9,N('Debt Payoff'!E10)) -> 40 | AB9: =MIN(T9,N('Debt Payoff'!E11)) -> 285 | AC9: =MIN(U9,N('Debt Payoff'!E12)) -> 160 | AD9: =MIN(V9,N('Debt Payoff'!E13)) -> 0 | AE9: =MIN(W9,N('Debt Payoff'!E14)) -> 0 | AF9: =MIN(X9,N('Debt Payoff'!E15)) -> 0 | AG9: =MIN(Y9,N('Debt Payoff'!E16)) -> 0 | AH9: =R9-Z9 -> 2656.1127 | AI9: =S9-AA9 -> 1221.124 | AJ9: =T9-AB9 -> 8171.5773 | AK9: =U9-AC9 -> 13836.136 | AL9: =V9-AD9 -> 0 | AM9: =W9-AE9 -> 0 | AN9: =X9-AF9 -> 0 | AO9: =Y9-AG9 -> 0 | AP9: =MAX(0,'Debt Payoff'!$D$17-SUM(Z9:AG9)) -> 200 | AQ9: =MIN(AH9,MAX(0,$AP9-SUMPRODUCT(($AH$1:$AO$1<AH$1)*$AH9:$AO9))) -> 200 | AR9: =MIN(AI9,MAX(0,$AP9-SUMPRODUCT(($AH$1:$AO$1<AI$1)*$AH9:$AO9))) -> 0 | AS9: =MIN(AJ9,MAX(0,$AP9-SUMPRODUCT(($AH$1:$AO$1<AJ$1)*$AH9:$AO9))) -> 0 | AT9: =MIN(AK9,MAX(0,$AP9-SUMPRODUCT(($AH$1:$AO$1<AK$1)*$AH9:$AO9))) -> 0 | AU9: =MIN(AL9,MAX(0,$AP9-SUMPRODUCT(($AH$1:$AO$1<AL$1)*$AH9:$AO9))) -> 0 | AV9: =MIN(AM9,MAX(0,$AP9-SUMPRODUCT(($AH$1:$AO$1<AM$1)*$AH9:$AO9))) -> 0 | AW9: =MIN(AN9,MAX(0,$AP9-SUMPRODUCT(($AH$1:$AO$1<AN$1)*$AH9:$AO9))) -> 0 | AX9: =MIN(AO9,MAX(0,$AP9-SUMPRODUCT(($AH$1:$AO$1<AO$1)*$AH9:$AO9))) -> 0 | AY9: =ROUND(AH9-AQ9,2) -> 2456.11 | AZ9: =ROUND(AI9-AR9,2) -> 1221.12 | BA9: =ROUND(AJ9-AS9,2) -> 8171.58 | BB9: =ROUND(AK9-AT9,2) -> 13836.14 | BC9: =ROUND(AL9-AU9,2) -> 0 | BD9: =ROUND(AM9-AV9,2) -> 0 | BE9: =ROUND(AN9-AW9,2) -> 0 | BF9: =ROUND(AO9-AX9,2) -> 0 | BG9: =SUM(AY9:BF9) -> 25684.95
A10: 8 | B10: =AY9 -> 2456.11 | C10: =AZ9 -> 1221.12 | D10: =BA9 -> 8171.58 | E10: =BB9 -> 13836.14 | F10: =BC9 -> 0 | G10: =BD9 -> 0 | H10: =BE9 -> 0 | I10: =BF9 -> 0 | J10: =B10*N('Debt Payoff'!D9)/12 -> 50.125112 | K10: =C10*N('Debt Payoff'!D10)/12 -> 20.341824 | L10: =D10*N('Debt Payoff'!D11)/12 -> 46.986585 | M10: =E10*N('Debt Payoff'!D12)/12 -> 63.415642 | N10: =F10*N('Debt Payoff'!D13)/12 -> 0 | O10: =G10*N('Debt Payoff'!D14)/12 -> 0 | P10: =H10*N('Debt Payoff'!D15)/12 -> 0 | Q10: =I10*N('Debt Payoff'!D16)/12 -> 0 | R10: =B10+J10 -> 2506.2351 | S10: =C10+K10 -> 1241.4618 | T10: =D10+L10 -> 8218.5666 | U10: =E10+M10 -> 13899.556 | V10: =F10+N10 -> 0 | W10: =G10+O10 -> 0 | X10: =H10+P10 -> 0 | Y10: =I10+Q10 -> 0 | Z10: =MIN(R10,N('Debt Payoff'!E9)) -> 120 | AA10: =MIN(S10,N('Debt Payoff'!E10)) -> 40 | AB10: =MIN(T10,N('Debt Payoff'!E11)) -> 285 | AC10: =MIN(U10,N('Debt Payoff'!E12)) -> 160 | AD10: =MIN(V10,N('Debt Payoff'!E13)) -> 0 | AE10: =MIN(W10,N('Debt Payoff'!E14)) -> 0 | AF10: =MIN(X10,N('Debt Payoff'!E15)) -> 0 | AG10: =MIN(Y10,N('Debt Payoff'!E16)) -> 0 | AH10: =R10-Z10 -> 2386.2351 | AI10: =S10-AA10 -> 1201.4618 | AJ10: =T10-AB10 -> 7933.5666 | AK10: =U10-AC10 -> 13739.556 | AL10: =V10-AD10 -> 0 | AM10: =W10-AE10 -> 0 | AN10: =X10-AF10 -> 0 | AO10: =Y10-AG10 -> 0 | AP10: =MAX(0,'Debt Payoff'!$D$17-SUM(Z10:AG10)) -> 200 | AQ10: =MIN(AH10,MAX(0,$AP10-SUMPRODUCT(($AH$1:$AO$1<AH$1)*$AH10:$AO10))) -> 200 | AR10: =MIN(AI10,MAX(0,$AP10-SUMPRODUCT(($AH$1:$AO$1<AI$1)*$AH10:$AO10))) -> 0 | AS10: =MIN(AJ10,MAX(0,$AP10-SUMPRODUCT(($AH$1:$AO$1<AJ$1)*$AH10:$AO10))) -> 0 | AT10: =MIN(AK10,MAX(0,$AP10-SUMPRODUCT(($AH$1:$AO$1<AK$1)*$AH10:$AO10))) -> 0 | AU10: =MIN(AL10,MAX(0,$AP10-SUMPRODUCT(($AH$1:$AO$1<AL$1)*$AH10:$AO10))) -> 0 | AV10: =MIN(AM10,MAX(0,$AP10-SUMPRODUCT(($AH$1:$AO$1<AM$1)*$AH10:$AO10))) -> 0 | AW10: =MIN(AN10,MAX(0,$AP10-SUMPRODUCT(($AH$1:$AO$1<AN$1)*$AH10:$AO10))) -> 0 | AX10: =MIN(AO10,MAX(0,$AP10-SUMPRODUCT(($AH$1:$AO$1<AO$1)*$AH10:$AO10))) -> 0 | AY10: =ROUND(AH10-AQ10,2) -> 2186.24 | AZ10: =ROUND(AI10-AR10,2) -> 1201.46 | BA10: =ROUND(AJ10-AS10,2) -> 7933.57 | BB10: =ROUND(AK10-AT10,2) -> 13739.56 | BC10: =ROUND(AL10-AU10,2) -> 0 | BD10: =ROUND(AM10-AV10,2) -> 0 | BE10: =ROUND(AN10-AW10,2) -> 0 | BF10: =ROUND(AO10-AX10,2) -> 0 | BG10: =SUM(AY10:BF10) -> 25060.83
A11: 9 | B11: =AY10 -> 2186.24 | C11: =AZ10 -> 1201.46 | D11: =BA10 -> 7933.57 | E11: =BB10 -> 13739.56 | F11: =BC10 -> 0 | G11: =BD10 -> 0 | H11: =BE10 -> 0 | I11: =BF10 -> 0 | J11: =B11*N('Debt Payoff'!D9)/12 -> 44.617515 | K11: =C11*N('Debt Payoff'!D10)/12 -> 20.014321 | L11: =D11*N('Debt Payoff'!D11)/12 -> 45.618027 | M11: =E11*N('Debt Payoff'!D12)/12 -> 62.972983 | N11: =F11*N('Debt Payoff'!D13)/12 -> 0 | O11: =G11*N('Debt Payoff'!D14)/12 -> 0 | P11: =H11*N('Debt Payoff'!D15)/12 -> 0 | Q11: =I11*N('Debt Payoff'!D16)/12 -> 0 | R11: =B11+J11 -> 2230.8575 | S11: =C11+K11 -> 1221.4743 | T11: =D11+L11 -> 7979.188 | U11: =E11+M11 -> 13802.533 | V11: =F11+N11 -> 0 | W11: =G11+O11 -> 0 | X11: =H11+P11 -> 0 | Y11: =I11+Q11 -> 0 | Z11: =MIN(R11,N('Debt Payoff'!E9)) -> 120 | AA11: =MIN(S11,N('Debt Payoff'!E10)) -> 40 | AB11: =MIN(T11,N('Debt Payoff'!E11)) -> 285 | AC11: =MIN(U11,N('Debt Payoff'!E12)) -> 160 | AD11: =MIN(V11,N('Debt Payoff'!E13)) -> 0 | AE11: =MIN(W11,N('Debt Payoff'!E14)) -> 0 | AF11: =MIN(X11,N('Debt Payoff'!E15)) -> 0 | AG11: =MIN(Y11,N('Debt Payoff'!E16)) -> 0 | AH11: =R11-Z11 -> 2110.8575 | AI11: =S11-AA11 -> 1181.4743 | AJ11: =T11-AB11 -> 7694.188 | AK11: =U11-AC11 -> 13642.533 | AL11: =V11-AD11 -> 0 | AM11: =W11-AE11 -> 0 | AN11: =X11-AF11 -> 0 | AO11: =Y11-AG11 -> 0 | AP11: =MAX(0,'Debt Payoff'!$D$17-SUM(Z11:AG11)) -> 200 | AQ11: =MIN(AH11,MAX(0,$AP11-SUMPRODUCT(($AH$1:$AO$1<AH$1)*$AH11:$AO11))) -> 200 | AR11: =MIN(AI11,MAX(0,$AP11-SUMPRODUCT(($AH$1:$AO$1<AI$1)*$AH11:$AO11))) -> 0 | AS11: =MIN(AJ11,MAX(0,$AP11-SUMPRODUCT(($AH$1:$AO$1<AJ$1)*$AH11:$AO11))) -> 0 | AT11: =MIN(AK11,MAX(0,$AP11-SUMPRODUCT(($AH$1:$AO$1<AK$1)*$AH11:$AO11))) -> 0 | AU11: =MIN(AL11,MAX(0,$AP11-SUMPRODUCT(($AH$1:$AO$1<AL$1)*$AH11:$AO11))) -> 0 | AV11: =MIN(AM11,MAX(0,$AP11-SUMPRODUCT(($AH$1:$AO$1<AM$1)*$AH11:$AO11))) -> 0 | AW11: =MIN(AN11,MAX(0,$AP11-SUMPRODUCT(($AH$1:$AO$1<AN$1)*$AH11:$AO11))) -> 0 | AX11: =MIN(AO11,MAX(0,$AP11-SUMPRODUCT(($AH$1:$AO$1<AO$1)*$AH11:$AO11))) -> 0 | AY11: =ROUND(AH11-AQ11,2) -> 1910.86 | AZ11: =ROUND(AI11-AR11,2) -> 1181.47 | BA11: =ROUND(AJ11-AS11,2) -> 7694.19 | BB11: =ROUND(AK11-AT11,2) -> 13642.53 | BC11: =ROUND(AL11-AU11,2) -> 0 | BD11: =ROUND(AM11-AV11,2) -> 0 | BE11: =ROUND(AN11-AW11,2) -> 0 | BF11: =ROUND(AO11-AX11,2) -> 0 | BG11: =SUM(AY11:BF11) -> 24429.05
A12: 10 | B12: =AY11 -> 1910.86 | C12: =AZ11 -> 1181.47 | D12: =BA11 -> 7694.19 | E12: =BB11 -> 13642.53 | F12: =BC11 -> 0 | G12: =BD11 -> 0 | H12: =BE11 -> 0 | I12: =BF11 -> 0 | J12: =B12*N('Debt Payoff'!D9)/12 -> 38.997468 | K12: =C12*N('Debt Payoff'!D10)/12 -> 19.681321 | L12: =D12*N('Debt Payoff'!D11)/12 -> 44.241593 | M12: =E12*N('Debt Payoff'!D12)/12 -> 62.528262 | N12: =F12*N('Debt Payoff'!D13)/12 -> 0 | O12: =G12*N('Debt Payoff'!D14)/12 -> 0 | P12: =H12*N('Debt Payoff'!D15)/12 -> 0 | Q12: =I12*N('Debt Payoff'!D16)/12 -> 0 | R12: =B12+J12 -> 1949.8575 | S12: =C12+K12 -> 1201.1513 | T12: =D12+L12 -> 7738.4316 | U12: =E12+M12 -> 13705.058 | V12: =F12+N12 -> 0 | W12: =G12+O12 -> 0 | X12: =H12+P12 -> 0 | Y12: =I12+Q12 -> 0 | Z12: =MIN(R12,N('Debt Payoff'!E9)) -> 120 | AA12: =MIN(S12,N('Debt Payoff'!E10)) -> 40 | AB12: =MIN(T12,N('Debt Payoff'!E11)) -> 285 | AC12: =MIN(U12,N('Debt Payoff'!E12)) -> 160 | AD12: =MIN(V12,N('Debt Payoff'!E13)) -> 0 | AE12: =MIN(W12,N('Debt Payoff'!E14)) -> 0 | AF12: =MIN(X12,N('Debt Payoff'!E15)) -> 0 | AG12: =MIN(Y12,N('Debt Payoff'!E16)) -> 0 | AH12: =R12-Z12 -> 1829.8575 | AI12: =S12-AA12 -> 1161.1513 | AJ12: =T12-AB12 -> 7453.4316 | AK12: =U12-AC12 -> 13545.058 | AL12: =V12-AD12 -> 0 | AM12: =W12-AE12 -> 0 | AN12: =X12-AF12 -> 0 | AO12: =Y12-AG12 -> 0 | AP12: =MAX(0,'Debt Payoff'!$D$17-SUM(Z12:AG12)) -> 200 | AQ12: =MIN(AH12,MAX(0,$AP12-SUMPRODUCT(($AH$1:$AO$1<AH$1)*$AH12:$AO12))) -> 200 | AR12: =MIN(AI12,MAX(0,$AP12-SUMPRODUCT(($AH$1:$AO$1<AI$1)*$AH12:$AO12))) -> 0 | AS12: =MIN(AJ12,MAX(0,$AP12-SUMPRODUCT(($AH$1:$AO$1<AJ$1)*$AH12:$AO12))) -> 0 | AT12: =MIN(AK12,MAX(0,$AP12-SUMPRODUCT(($AH$1:$AO$1<AK$1)*$AH12:$AO12))) -> 0 | AU12: =MIN(AL12,MAX(0,$AP12-SUMPRODUCT(($AH$1:$AO$1<AL$1)*$AH12:$AO12))) -> 0 | AV12: =MIN(AM12,MAX(0,$AP12-SUMPRODUCT(($AH$1:$AO$1<AM$1)*$AH12:$AO12))) -> 0 | AW12: =MIN(AN12,MAX(0,$AP12-SUMPRODUCT(($AH$1:$AO$1<AN$1)*$AH12:$AO12))) -> 0 | AX12: =MIN(AO12,MAX(0,$AP12-SUMPRODUCT(($AH$1:$AO$1<AO$1)*$AH12:$AO12))) -> 0 | AY12: =ROUND(AH12-AQ12,2) -> 1629.86 | AZ12: =ROUND(AI12-AR12,2) -> 1161.15 | BA12: =ROUND(AJ12-AS12,2) -> 7453.43 | BB12: =ROUND(AK12-AT12,2) -> 13545.06 | BC12: =ROUND(AL12-AU12,2) -> 0 | BD12: =ROUND(AM12-AV12,2) -> 0 | BE12: =ROUND(AN12-AW12,2) -> 0 | BF12: =ROUND(AO12-AX12,2) -> 0 | BG12: =SUM(AY12:BF12) -> 23789.5
A13: 11 | B13: =AY12 -> 1629.86 | C13: =AZ12 -> 1161.15 | D13: =BA12 -> 7453.43 | E13: =BB12 -> 13545.06 | F13: =BC12 -> 0 | G13: =BD12 -> 0 | H13: =BE12 -> 0 | I13: =BF12 -> 0 | J13: =B13*N('Debt Payoff'!D9)/12 -> 33.262726 | K13: =C13*N('Debt Payoff'!D10)/12 -> 19.342824 | L13: =D13*N('Debt Payoff'!D11)/12 -> 42.857222 | M13: =E13*N('Debt Payoff'!D12)/12 -> 62.081525 | N13: =F13*N('Debt Payoff'!D13)/12 -> 0 | O13: =G13*N('Debt Payoff'!D14)/12 -> 0 | P13: =H13*N('Debt Payoff'!D15)/12 -> 0 | Q13: =I13*N('Debt Payoff'!D16)/12 -> 0 | R13: =B13+J13 -> 1663.1227 | S13: =C13+K13 -> 1180.4928 | T13: =D13+L13 -> 7496.2872 | U13: =E13+M13 -> 13607.142 | V13: =F13+N13 -> 0 | W13: =G13+O13 -> 0 | X13: =H13+P13 -> 0 | Y13: =I13+Q13 -> 0 | Z13: =MIN(R13,N('Debt Payoff'!E9)) -> 120 | AA13: =MIN(S13,N('Debt Payoff'!E10)) -> 40 | AB13: =MIN(T13,N('Debt Payoff'!E11)) -> 285 | AC13: =MIN(U13,N('Debt Payoff'!E12)) -> 160 | AD13: =MIN(V13,N('Debt Payoff'!E13)) -> 0 | AE13: =MIN(W13,N('Debt Payoff'!E14)) -> 0 | AF13: =MIN(X13,N('Debt Payoff'!E15)) -> 0 | AG13: =MIN(Y13,N('Debt Payoff'!E16)) -> 0 | AH13: =R13-Z13 -> 1543.1227 | AI13: =S13-AA13 -> 1140.4928 | AJ13: =T13-AB13 -> 7211.2872 | AK13: =U13-AC13 -> 13447.142 | AL13: =V13-AD13 -> 0 | AM13: =W13-AE13 -> 0 | AN13: =X13-AF13 -> 0 | AO13: =Y13-AG13 -> 0 | AP13: =MAX(0,'Debt Payoff'!$D$17-SUM(Z13:AG13)) -> 200 | AQ13: =MIN(AH13,MAX(0,$AP13-SUMPRODUCT(($AH$1:$AO$1<AH$1)*$AH13:$AO13))) -> 200 | AR13: =MIN(AI13,MAX(0,$AP13-SUMPRODUCT(($AH$1:$AO$1<AI$1)*$AH13:$AO13))) -> 0 | AS13: =MIN(AJ13,MAX(0,$AP13-SUMPRODUCT(($AH$1:$AO$1<AJ$1)*$AH13:$AO13))) -> 0 | AT13: =MIN(AK13,MAX(0,$AP13-SUMPRODUCT(($AH$1:$AO$1<AK$1)*$AH13:$AO13))) -> 0 | AU13: =MIN(AL13,MAX(0,$AP13-SUMPRODUCT(($AH$1:$AO$1<AL$1)*$AH13:$AO13))) -> 0 | AV13: =MIN(AM13,MAX(0,$AP13-SUMPRODUCT(($AH$1:$AO$1<AM$1)*$AH13:$AO13))) -> 0 | AW13: =MIN(AN13,MAX(0,$AP13-SUMPRODUCT(($AH$1:$AO$1<AN$1)*$AH13:$AO13))) -> 0 | AX13: =MIN(AO13,MAX(0,$AP13-SUMPRODUCT(($AH$1:$AO$1<AO$1)*$AH13:$AO13))) -> 0 | AY13: =ROUND(AH13-AQ13,2) -> 1343.12 | AZ13: =ROUND(AI13-AR13,2) -> 1140.49 | BA13: =ROUND(AJ13-AS13,2) -> 7211.29 | BB13: =ROUND(AK13-AT13,2) -> 13447.14 | BC13: =ROUND(AL13-AU13,2) -> 0 | BD13: =ROUND(AM13-AV13,2) -> 0 | BE13: =ROUND(AN13-AW13,2) -> 0 | BF13: =ROUND(AO13-AX13,2) -> 0 | BG13: =SUM(AY13:BF13) -> 23142.04
A14: 12 | B14: =AY13 -> 1343.12 | C14: =AZ13 -> 1140.49 | D14: =BA13 -> 7211.29 | E14: =BB13 -> 13447.14 | F14: =BC13 -> 0 | G14: =BD13 -> 0 | H14: =BE13 -> 0 | I14: =BF13 -> 0 | J14: =B14*N('Debt Payoff'!D9)/12 -> 27.410841 | K14: =C14*N('Debt Payoff'!D10)/12 -> 18.998663 | L14: =D14*N('Debt Payoff'!D11)/12 -> 41.464917 | M14: =E14*N('Debt Payoff'!D12)/12 -> 61.632725 | N14: =F14*N('Debt Payoff'!D13)/12 -> 0 | O14: =G14*N('Debt Payoff'!D14)/12 -> 0 | P14: =H14*N('Debt Payoff'!D15)/12 -> 0 | Q14: =I14*N('Debt Payoff'!D16)/12 -> 0 | R14: =B14+J14 -> 1370.5308 | S14: =C14+K14 -> 1159.4887 | T14: =D14+L14 -> 7252.7549 | U14: =E14+M14 -> 13508.773 | V14: =F14+N14 -> 0 | W14: =G14+O14 -> 0 | X14: =H14+P14 -> 0 | Y14: =I14+Q14 -> 0 | Z14: =MIN(R14,N('Debt Payoff'!E9)) -> 120 | AA14: =MIN(S14,N('Debt Payoff'!E10)) -> 40 | AB14: =MIN(T14,N('Debt Payoff'!E11)) -> 285 | AC14: =MIN(U14,N('Debt Payoff'!E12)) -> 160 | AD14: =MIN(V14,N('Debt Payoff'!E13)) -> 0 | AE14: =MIN(W14,N('Debt Payoff'!E14)) -> 0 | AF14: =MIN(X14,N('Debt Payoff'!E15)) -> 0 | AG14: =MIN(Y14,N('Debt Payoff'!E16)) -> 0 | AH14: =R14-Z14 -> 1250.5308 | AI14: =S14-AA14 -> 1119.4887 | AJ14: =T14-AB14 -> 6967.7549 | AK14: =U14-AC14 -> 13348.773 | AL14: =V14-AD14 -> 0 | AM14: =W14-AE14 -> 0 | AN14: =X14-AF14 -> 0 | AO14: =Y14-AG14 -> 0 | AP14: =MAX(0,'Debt Payoff'!$D$17-SUM(Z14:AG14)) -> 200 | AQ14: =MIN(AH14,MAX(0,$AP14-SUMPRODUCT(($AH$1:$AO$1<AH$1)*$AH14:$AO14))) -> 200 | AR14: =MIN(AI14,MAX(0,$AP14-SUMPRODUCT(($AH$1:$AO$1<AI$1)*$AH14:$AO14))) -> 0 | AS14: =MIN(AJ14,MAX(0,$AP14-SUMPRODUCT(($AH$1:$AO$1<AJ$1)*$AH14:$AO14))) -> 0 | AT14: =MIN(AK14,MAX(0,$AP14-SUMPRODUCT(($AH$1:$AO$1<AK$1)*$AH14:$AO14))) -> 0 | AU14: =MIN(AL14,MAX(0,$AP14-SUMPRODUCT(($AH$1:$AO$1<AL$1)*$AH14:$AO14))) -> 0 | AV14: =MIN(AM14,MAX(0,$AP14-SUMPRODUCT(($AH$1:$AO$1<AM$1)*$AH14:$AO14))) -> 0 | AW14: =MIN(AN14,MAX(0,$AP14-SUMPRODUCT(($AH$1:$AO$1<AN$1)*$AH14:$AO14))) -> 0 | AX14: =MIN(AO14,MAX(0,$AP14-SUMPRODUCT(($AH$1:$AO$1<AO$1)*$AH14:$AO14))) -> 0 | AY14: =ROUND(AH14-AQ14,2) -> 1050.53 | AZ14: =ROUND(AI14-AR14,2) -> 1119.49 | BA14: =ROUND(AJ14-AS14,2) -> 6967.75 | BB14: =ROUND(AK14-AT14,2) -> 13348.77 | BC14: =ROUND(AL14-AU14,2) -> 0 | BD14: =ROUND(AM14-AV14,2) -> 0 | BE14: =ROUND(AN14-AW14,2) -> 0 | BF14: =ROUND(AO14-AX14,2) -> 0 | BG14: =SUM(AY14:BF14) -> 22486.54
A15: 13 | B15: =AY14 -> 1050.53 | C15: =AZ14 -> 1119.49 | D15: =BA14 -> 6967.75 | E15: =BB14 -> 13348.77 | F15: =BC14 -> 0 | G15: =BD14 -> 0 | H15: =BE14 -> 0 | I15: =BF14 -> 0 | J15: =B15*N('Debt Payoff'!D9)/12 -> 21.439566 | K15: =C15*N('Debt Payoff'!D10)/12 -> 18.648838 | L15: =D15*N('Debt Payoff'!D11)/12 -> 40.064563 | M15: =E15*N('Debt Payoff'!D12)/12 -> 61.181863 | N15: =F15*N('Debt Payoff'!D13)/12 -> 0 | O15: =G15*N('Debt Payoff'!D14)/12 -> 0 | P15: =H15*N('Debt Payoff'!D15)/12 -> 0 | Q15: =I15*N('Debt Payoff'!D16)/12 -> 0 | R15: =B15+J15 -> 1071.9696 | S15: =C15+K15 -> 1138.1388 | T15: =D15+L15 -> 7007.8146 | U15: =E15+M15 -> 13409.952 | V15: =F15+N15 -> 0 | W15: =G15+O15 -> 0 | X15: =H15+P15 -> 0 | Y15: =I15+Q15 -> 0 | Z15: =MIN(R15,N('Debt Payoff'!E9)) -> 120 | AA15: =MIN(S15,N('Debt Payoff'!E10)) -> 40 | AB15: =MIN(T15,N('Debt Payoff'!E11)) -> 285 | AC15: =MIN(U15,N('Debt Payoff'!E12)) -> 160 | AD15: =MIN(V15,N('Debt Payoff'!E13)) -> 0 | AE15: =MIN(W15,N('Debt Payoff'!E14)) -> 0 | AF15: =MIN(X15,N('Debt Payoff'!E15)) -> 0 | AG15: =MIN(Y15,N('Debt Payoff'!E16)) -> 0 | AH15: =R15-Z15 -> 951.96957 | AI15: =S15-AA15 -> 1098.1388 | AJ15: =T15-AB15 -> 6722.8146 | AK15: =U15-AC15 -> 13249.952 | AL15: =V15-AD15 -> 0 | AM15: =W15-AE15 -> 0 | AN15: =X15-AF15 -> 0 | AO15: =Y15-AG15 -> 0 | AP15: =MAX(0,'Debt Payoff'!$D$17-SUM(Z15:AG15)) -> 200 | AQ15: =MIN(AH15,MAX(0,$AP15-SUMPRODUCT(($AH$1:$AO$1<AH$1)*$AH15:$AO15))) -> 200 | AR15: =MIN(AI15,MAX(0,$AP15-SUMPRODUCT(($AH$1:$AO$1<AI$1)*$AH15:$AO15))) -> 0 | AS15: =MIN(AJ15,MAX(0,$AP15-SUMPRODUCT(($AH$1:$AO$1<AJ$1)*$AH15:$AO15))) -> 0 | AT15: =MIN(AK15,MAX(0,$AP15-SUMPRODUCT(($AH$1:$AO$1<AK$1)*$AH15:$AO15))) -> 0 | AU15: =MIN(AL15,MAX(0,$AP15-SUMPRODUCT(($AH$1:$AO$1<AL$1)*$AH15:$AO15))) -> 0 | AV15: =MIN(AM15,MAX(0,$AP15-SUMPRODUCT(($AH$1:$AO$1<AM$1)*$AH15:$AO15))) -> 0 | AW15: =MIN(AN15,MAX(0,$AP15-SUMPRODUCT(($AH$1:$AO$1<AN$1)*$AH15:$AO15))) -> 0 | AX15: =MIN(AO15,MAX(0,$AP15-SUMPRODUCT(($AH$1:$AO$1<AO$1)*$AH15:$AO15))) -> 0 | AY15: =ROUND(AH15-AQ15,2) -> 751.97 | AZ15: =ROUND(AI15-AR15,2) -> 1098.14 | BA15: =ROUND(AJ15-AS15,2) -> 6722.81 | BB15: =ROUND(AK15-AT15,2) -> 13249.95 | BC15: =ROUND(AL15-AU15,2) -> 0 | BD15: =ROUND(AM15-AV15,2) -> 0 | BE15: =ROUND(AN15-AW15,2) -> 0 | BF15: =ROUND(AO15-AX15,2) -> 0 | BG15: =SUM(AY15:BF15) -> 21822.87
A16: 14 | B16: =AY15 -> 751.97 | C16: =AZ15 -> 1098.14 | D16: =BA15 -> 6722.81 | E16: =BB15 -> 13249.95 | F16: =BC15 -> 0 | G16: =BD15 -> 0 | H16: =BE15 -> 0 | I16: =BF15 -> 0 | J16: =B16*N('Debt Payoff'!D9)/12 -> 15.346454 | K16: =C16*N('Debt Payoff'!D10)/12 -> 18.293182 | L16: =D16*N('Debt Payoff'!D11)/12 -> 38.656157 | M16: =E16*N('Debt Payoff'!D12)/12 -> 60.728938 | N16: =F16*N('Debt Payoff'!D13)/12 -> 0 | O16: =G16*N('Debt Payoff'!D14)/12 -> 0 | P16: =H16*N('Debt Payoff'!D15)/12 -> 0 | Q16: =I16*N('Debt Payoff'!D16)/12 -> 0 | R16: =B16+J16 -> 767.31645 | S16: =C16+K16 -> 1116.4332 | T16: =D16+L16 -> 6761.4662 | U16: =E16+M16 -> 13310.679 | V16: =F16+N16 -> 0 | W16: =G16+O16 -> 0 | X16: =H16+P16 -> 0 | Y16: =I16+Q16 -> 0 | Z16: =MIN(R16,N('Debt Payoff'!E9)) -> 120 | AA16: =MIN(S16,N('Debt Payoff'!E10)) -> 40 | AB16: =MIN(T16,N('Debt Payoff'!E11)) -> 285 | AC16: =MIN(U16,N('Debt Payoff'!E12)) -> 160 | AD16: =MIN(V16,N('Debt Payoff'!E13)) -> 0 | AE16: =MIN(W16,N('Debt Payoff'!E14)) -> 0 | AF16: =MIN(X16,N('Debt Payoff'!E15)) -> 0 | AG16: =MIN(Y16,N('Debt Payoff'!E16)) -> 0 | AH16: =R16-Z16 -> 647.31645 | AI16: =S16-AA16 -> 1076.4332 | AJ16: =T16-AB16 -> 6476.4662 | AK16: =U16-AC16 -> 13150.679 | AL16: =V16-AD16 -> 0 | AM16: =W16-AE16 -> 0 | AN16: =X16-AF16 -> 0 | AO16: =Y16-AG16 -> 0 | AP16: =MAX(0,'Debt Payoff'!$D$17-SUM(Z16:AG16)) -> 200 | AQ16: =MIN(AH16,MAX(0,$AP16-SUMPRODUCT(($AH$1:$AO$1<AH$1)*$AH16:$AO16))) -> 200 | AR16: =MIN(AI16,MAX(0,$AP16-SUMPRODUCT(($AH$1:$AO$1<AI$1)*$AH16:$AO16))) -> 0 | AS16: =MIN(AJ16,MAX(0,$AP16-SUMPRODUCT(($AH$1:$AO$1<AJ$1)*$AH16:$AO16))) -> 0 | AT16: =MIN(AK16,MAX(0,$AP16-SUMPRODUCT(($AH$1:$AO$1<AK$1)*$AH16:$AO16))) -> 0 | AU16: =MIN(AL16,MAX(0,$AP16-SUMPRODUCT(($AH$1:$AO$1<AL$1)*$AH16:$AO16))) -> 0 | AV16: =MIN(AM16,MAX(0,$AP16-SUMPRODUCT(($AH$1:$AO$1<AM$1)*$AH16:$AO16))) -> 0 | AW16: =MIN(AN16,MAX(0,$AP16-SUMPRODUCT(($AH$1:$AO$1<AN$1)*$AH16:$AO16))) -> 0 | AX16: =MIN(AO16,MAX(0,$AP16-SUMPRODUCT(($AH$1:$AO$1<AO$1)*$AH16:$AO16))) -> 0 | AY16: =ROUND(AH16-AQ16,2) -> 447.32 | AZ16: =ROUND(AI16-AR16,2) -> 1076.43 | BA16: =ROUND(AJ16-AS16,2) -> 6476.47 | BB16: =ROUND(AK16-AT16,2) -> 13150.68 | BC16: =ROUND(AL16-AU16,2) -> 0 | BD16: =ROUND(AM16-AV16,2) -> 0 | BE16: =ROUND(AN16-AW16,2) -> 0 | BF16: =ROUND(AO16-AX16,2) -> 0 | BG16: =SUM(AY16:BF16) -> 21150.9
A17: 15 | B17: =AY16 -> 447.32 | C17: =AZ16 -> 1076.43 | D17: =BA16 -> 6476.47 | E17: =BB16 -> 13150.68 | F17: =BC16 -> 0 | G17: =BD16 -> 0 | H17: =BE16 -> 0 | I17: =BF16 -> 0 | J17: =B17*N('Debt Payoff'!D9)/12 -> 9.1290557 | K17: =C17*N('Debt Payoff'!D10)/12 -> 17.93153 | L17: =D17*N('Debt Payoff'!D11)/12 -> 37.239702 | M17: =E17*N('Debt Payoff'!D12)/12 -> 60.27395 | N17: =F17*N('Debt Payoff'!D13)/12 -> 0 | O17: =G17*N('Debt Payoff'!D14)/12 -> 0 | P17: =H17*N('Debt Payoff'!D15)/12 -> 0 | Q17: =I17*N('Debt Payoff'!D16)/12 -> 0 | R17: =B17+J17 -> 456.44906 | S17: =C17+K17 -> 1094.3615 | T17: =D17+L17 -> 6513.7097 | U17: =E17+M17 -> 13210.954 | V17: =F17+N17 -> 0 | W17: =G17+O17 -> 0 | X17: =H17+P17 -> 0 | Y17: =I17+Q17 -> 0 | Z17: =MIN(R17,N('Debt Payoff'!E9)) -> 120 | AA17: =MIN(S17,N('Debt Payoff'!E10)) -> 40 | AB17: =MIN(T17,N('Debt Payoff'!E11)) -> 285 | AC17: =MIN(U17,N('Debt Payoff'!E12)) -> 160 | AD17: =MIN(V17,N('Debt Payoff'!E13)) -> 0 | AE17: =MIN(W17,N('Debt Payoff'!E14)) -> 0 | AF17: =MIN(X17,N('Debt Payoff'!E15)) -> 0 | AG17: =MIN(Y17,N('Debt Payoff'!E16)) -> 0 | AH17: =R17-Z17 -> 336.44906 | AI17: =S17-AA17 -> 1054.3615 | AJ17: =T17-AB17 -> 6228.7097 | AK17: =U17-AC17 -> 13050.954 | AL17: =V17-AD17 -> 0 | AM17: =W17-AE17 -> 0 | AN17: =X17-AF17 -> 0 | AO17: =Y17-AG17 -> 0 | AP17: =MAX(0,'Debt Payoff'!$D$17-SUM(Z17:AG17)) -> 200 | AQ17: =MIN(AH17,MAX(0,$AP17-SUMPRODUCT(($AH$1:$AO$1<AH$1)*$AH17:$AO17))) -> 200 | AR17: =MIN(AI17,MAX(0,$AP17-SUMPRODUCT(($AH$1:$AO$1<AI$1)*$AH17:$AO17))) -> 0 | AS17: =MIN(AJ17,MAX(0,$AP17-SUMPRODUCT(($AH$1:$AO$1<AJ$1)*$AH17:$AO17))) -> 0 | AT17: =MIN(AK17,MAX(0,$AP17-SUMPRODUCT(($AH$1:$AO$1<AK$1)*$AH17:$AO17))) -> 0 | AU17: =MIN(AL17,MAX(0,$AP17-SUMPRODUCT(($AH$1:$AO$1<AL$1)*$AH17:$AO17))) -> 0 | AV17: =MIN(AM17,MAX(0,$AP17-SUMPRODUCT(($AH$1:$AO$1<AM$1)*$AH17:$AO17))) -> 0 | AW17: =MIN(AN17,MAX(0,$AP17-SUMPRODUCT(($AH$1:$AO$1<AN$1)*$AH17:$AO17))) -> 0 | AX17: =MIN(AO17,MAX(0,$AP17-SUMPRODUCT(($AH$1:$AO$1<AO$1)*$AH17:$AO17))) -> 0 | AY17: =ROUND(AH17-AQ17,2) -> 136.45 | AZ17: =ROUND(AI17-AR17,2) -> 1054.36 | BA17: =ROUND(AJ17-AS17,2) -> 6228.71 | BB17: =ROUND(AK17-AT17,2) -> 13050.95 | BC17: =ROUND(AL17-AU17,2) -> 0 | BD17: =ROUND(AM17-AV17,2) -> 0 | BE17: =ROUND(AN17-AW17,2) -> 0 | BF17: =ROUND(AO17-AX17,2) -> 0 | BG17: =SUM(AY17:BF17) -> 20470.47
A18: 16 | B18: =AY17 -> 136.45 | C18: =AZ17 -> 1054.36 | D18: =BA17 -> 6228.71 | E18: =BB17 -> 13050.95 | F18: =BC17 -> 0 | G18: =BD17 -> 0 | H18: =BE17 -> 0 | I18: =BF17 -> 0 | J18: =B18*N('Debt Payoff'!D9)/12 -> 2.7847171 | K18: =C18*N('Debt Payoff'!D10)/12 -> 17.56388 | L18: =D18*N('Debt Payoff'!D11)/12 -> 35.815083 | M18: =E18*N('Debt Payoff'!D12)/12 -> 59.816854 | N18: =F18*N('Debt Payoff'!D13)/12 -> 0 | O18: =G18*N('Debt Payoff'!D14)/12 -> 0 | P18: =H18*N('Debt Payoff'!D15)/12 -> 0 | Q18: =I18*N('Debt Payoff'!D16)/12 -> 0 | R18: =B18+J18 -> 139.23472 | S18: =C18+K18 -> 1071.9239 | T18: =D18+L18 -> 6264.5251 | U18: =E18+M18 -> 13110.767 | V18: =F18+N18 -> 0 | W18: =G18+O18 -> 0 | X18: =H18+P18 -> 0 | Y18: =I18+Q18 -> 0 | Z18: =MIN(R18,N('Debt Payoff'!E9)) -> 120 | AA18: =MIN(S18,N('Debt Payoff'!E10)) -> 40 | AB18: =MIN(T18,N('Debt Payoff'!E11)) -> 285 | AC18: =MIN(U18,N('Debt Payoff'!E12)) -> 160 | AD18: =MIN(V18,N('Debt Payoff'!E13)) -> 0 | AE18: =MIN(W18,N('Debt Payoff'!E14)) -> 0 | AF18: =MIN(X18,N('Debt Payoff'!E15)) -> 0 | AG18: =MIN(Y18,N('Debt Payoff'!E16)) -> 0 | AH18: =R18-Z18 -> 19.234717 | AI18: =S18-AA18 -> 1031.9239 | AJ18: =T18-AB18 -> 5979.5251 | AK18: =U18-AC18 -> 12950.767 | AL18: =V18-AD18 -> 0 | AM18: =W18-AE18 -> 0 | AN18: =X18-AF18 -> 0 | AO18: =Y18-AG18 -> 0 | AP18: =MAX(0,'Debt Payoff'!$D$17-SUM(Z18:AG18)) -> 200 | AQ18: =MIN(AH18,MAX(0,$AP18-SUMPRODUCT(($AH$1:$AO$1<AH$1)*$AH18:$AO18))) -> 19.234717 | AR18: =MIN(AI18,MAX(0,$AP18-SUMPRODUCT(($AH$1:$AO$1<AI$1)*$AH18:$AO18))) -> 180.76528 | AS18: =MIN(AJ18,MAX(0,$AP18-SUMPRODUCT(($AH$1:$AO$1<AJ$1)*$AH18:$AO18))) -> 0 | AT18: =MIN(AK18,MAX(0,$AP18-SUMPRODUCT(($AH$1:$AO$1<AK$1)*$AH18:$AO18))) -> 0 | AU18: =MIN(AL18,MAX(0,$AP18-SUMPRODUCT(($AH$1:$AO$1<AL$1)*$AH18:$AO18))) -> 0 | AV18: =MIN(AM18,MAX(0,$AP18-SUMPRODUCT(($AH$1:$AO$1<AM$1)*$AH18:$AO18))) -> 0 | AW18: =MIN(AN18,MAX(0,$AP18-SUMPRODUCT(($AH$1:$AO$1<AN$1)*$AH18:$AO18))) -> 0 | AX18: =MIN(AO18,MAX(0,$AP18-SUMPRODUCT(($AH$1:$AO$1<AO$1)*$AH18:$AO18))) -> 0 | AY18: =ROUND(AH18-AQ18,2) -> 0 | AZ18: =ROUND(AI18-AR18,2) -> 851.16 | BA18: =ROUND(AJ18-AS18,2) -> 5979.53 | BB18: =ROUND(AK18-AT18,2) -> 12950.77 | BC18: =ROUND(AL18-AU18,2) -> 0 | BD18: =ROUND(AM18-AV18,2) -> 0 | BE18: =ROUND(AN18-AW18,2) -> 0 | BF18: =ROUND(AO18-AX18,2) -> 0 | BG18: =SUM(AY18:BF18) -> 19781.46
A19: 17 | B19: =AY18 -> 0 | C19: =AZ18 -> 851.16 | D19: =BA18 -> 5979.53 | E19: =BB18 -> 12950.77 | F19: =BC18 -> 0 | G19: =BD18 -> 0 | H19: =BE18 -> 0 | I19: =BF18 -> 0 | J19: =B19*N('Debt Payoff'!D9)/12 -> 0 | K19: =C19*N('Debt Payoff'!D10)/12 -> 14.178907 | L19: =D19*N('Debt Payoff'!D11)/12 -> 34.382297 | M19: =E19*N('Debt Payoff'!D12)/12 -> 59.357696 | N19: =F19*N('Debt Payoff'!D13)/12 -> 0 | O19: =G19*N('Debt Payoff'!D14)/12 -> 0 | P19: =H19*N('Debt Payoff'!D15)/12 -> 0 | Q19: =I19*N('Debt Payoff'!D16)/12 -> 0 | R19: =B19+J19 -> 0 | S19: =C19+K19 -> 865.33891 | T19: =D19+L19 -> 6013.9123 | U19: =E19+M19 -> 13010.128 | V19: =F19+N19 -> 0 | W19: =G19+O19 -> 0 | X19: =H19+P19 -> 0 | Y19: =I19+Q19 -> 0 | Z19: =MIN(R19,N('Debt Payoff'!E9)) -> 0 | AA19: =MIN(S19,N('Debt Payoff'!E10)) -> 40 | AB19: =MIN(T19,N('Debt Payoff'!E11)) -> 285 | AC19: =MIN(U19,N('Debt Payoff'!E12)) -> 160 | AD19: =MIN(V19,N('Debt Payoff'!E13)) -> 0 | AE19: =MIN(W19,N('Debt Payoff'!E14)) -> 0 | AF19: =MIN(X19,N('Debt Payoff'!E15)) -> 0 | AG19: =MIN(Y19,N('Debt Payoff'!E16)) -> 0 | AH19: =R19-Z19 -> 0 | AI19: =S19-AA19 -> 825.33891 | AJ19: =T19-AB19 -> 5728.9123 | AK19: =U19-AC19 -> 12850.128 | AL19: =V19-AD19 -> 0 | AM19: =W19-AE19 -> 0 | AN19: =X19-AF19 -> 0 | AO19: =Y19-AG19 -> 0 | AP19: =MAX(0,'Debt Payoff'!$D$17-SUM(Z19:AG19)) -> 320 | AQ19: =MIN(AH19,MAX(0,$AP19-SUMPRODUCT(($AH$1:$AO$1<AH$1)*$AH19:$AO19))) -> 0 | AR19: =MIN(AI19,MAX(0,$AP19-SUMPRODUCT(($AH$1:$AO$1<AI$1)*$AH19:$AO19))) -> 320 | AS19: =MIN(AJ19,MAX(0,$AP19-SUMPRODUCT(($AH$1:$AO$1<AJ$1)*$AH19:$AO19))) -> 0 | AT19: =MIN(AK19,MAX(0,$AP19-SUMPRODUCT(($AH$1:$AO$1<AK$1)*$AH19:$AO19))) -> 0 | AU19: =MIN(AL19,MAX(0,$AP19-SUMPRODUCT(($AH$1:$AO$1<AL$1)*$AH19:$AO19))) -> 0 | AV19: =MIN(AM19,MAX(0,$AP19-SUMPRODUCT(($AH$1:$AO$1<AM$1)*$AH19:$AO19))) -> 0 | AW19: =MIN(AN19,MAX(0,$AP19-SUMPRODUCT(($AH$1:$AO$1<AN$1)*$AH19:$AO19))) -> 0 | AX19: =MIN(AO19,MAX(0,$AP19-SUMPRODUCT(($AH$1:$AO$1<AO$1)*$AH19:$AO19))) -> 0 | AY19: =ROUND(AH19-AQ19,2) -> 0 | AZ19: =ROUND(AI19-AR19,2) -> 505.34 | BA19: =ROUND(AJ19-AS19,2) -> 5728.91 | BB19: =ROUND(AK19-AT19,2) -> 12850.13 | BC19: =ROUND(AL19-AU19,2) -> 0 | BD19: =ROUND(AM19-AV19,2) -> 0 | BE19: =ROUND(AN19-AW19,2) -> 0 | BF19: =ROUND(AO19-AX19,2) -> 0 | BG19: =SUM(AY19:BF19) -> 19084.38
A20: 18 | B20: =AY19 -> 0 | C20: =AZ19 -> 505.34 | D20: =BA19 -> 5728.91 | E20: =BB19 -> 12850.13 | F20: =BC19 -> 0 | G20: =BD19 -> 0 | H20: =BE19 -> 0 | I20: =BF19 -> 0 | J20: =B20*N('Debt Payoff'!D9)/12 -> 0 | K20: =C20*N('Debt Payoff'!D10)/12 -> 8.4181222 | L20: =D20*N('Debt Payoff'!D11)/12 -> 32.941232 | M20: =E20*N('Debt Payoff'!D12)/12 -> 58.896429 | N20: =F20*N('Debt Payoff'!D13)/12 -> 0 | O20: =G20*N('Debt Payoff'!D14)/12 -> 0 | P20: =H20*N('Debt Payoff'!D15)/12 -> 0 | Q20: =I20*N('Debt Payoff'!D16)/12 -> 0 | R20: =B20+J20 -> 0 | S20: =C20+K20 -> 513.75812 | T20: =D20+L20 -> 5761.8512 | U20: =E20+M20 -> 12909.026 | V20: =F20+N20 -> 0 | W20: =G20+O20 -> 0 | X20: =H20+P20 -> 0 | Y20: =I20+Q20 -> 0 | Z20: =MIN(R20,N('Debt Payoff'!E9)) -> 0 | AA20: =MIN(S20,N('Debt Payoff'!E10)) -> 40 | AB20: =MIN(T20,N('Debt Payoff'!E11)) -> 285 | AC20: =MIN(U20,N('Debt Payoff'!E12)) -> 160 | AD20: =MIN(V20,N('Debt Payoff'!E13)) -> 0 | AE20: =MIN(W20,N('Debt Payoff'!E14)) -> 0 | AF20: =MIN(X20,N('Debt Payoff'!E15)) -> 0 | AG20: =MIN(Y20,N('Debt Payoff'!E16)) -> 0 | AH20: =R20-Z20 -> 0 | AI20: =S20-AA20 -> 473.75812 | AJ20: =T20-AB20 -> 5476.8512 | AK20: =U20-AC20 -> 12749.026 | AL20: =V20-AD20 -> 0 | AM20: =W20-AE20 -> 0 | AN20: =X20-AF20 -> 0 | AO20: =Y20-AG20 -> 0 | AP20: =MAX(0,'Debt Payoff'!$D$17-SUM(Z20:AG20)) -> 320 | AQ20: =MIN(AH20,MAX(0,$AP20-SUMPRODUCT(($AH$1:$AO$1<AH$1)*$AH20:$AO20))) -> 0 | AR20: =MIN(AI20,MAX(0,$AP20-SUMPRODUCT(($AH$1:$AO$1<AI$1)*$AH20:$AO20))) -> 320 | AS20: =MIN(AJ20,MAX(0,$AP20-SUMPRODUCT(($AH$1:$AO$1<AJ$1)*$AH20:$AO20))) -> 0 | AT20: =MIN(AK20,MAX(0,$AP20-SUMPRODUCT(($AH$1:$AO$1<AK$1)*$AH20:$AO20))) -> 0 | AU20: =MIN(AL20,MAX(0,$AP20-SUMPRODUCT(($AH$1:$AO$1<AL$1)*$AH20:$AO20))) -> 0 | AV20: =MIN(AM20,MAX(0,$AP20-SUMPRODUCT(($AH$1:$AO$1<AM$1)*$AH20:$AO20))) -> 0 | AW20: =MIN(AN20,MAX(0,$AP20-SUMPRODUCT(($AH$1:$AO$1<AN$1)*$AH20:$AO20))) -> 0 | AX20: =MIN(AO20,MAX(0,$AP20-SUMPRODUCT(($AH$1:$AO$1<AO$1)*$AH20:$AO20))) -> 0 | AY20: =ROUND(AH20-AQ20,2) -> 0 | AZ20: =ROUND(AI20-AR20,2) -> 153.76 | BA20: =ROUND(AJ20-AS20,2) -> 5476.85 | BB20: =ROUND(AK20-AT20,2) -> 12749.03 | BC20: =ROUND(AL20-AU20,2) -> 0 | BD20: =ROUND(AM20-AV20,2) -> 0 | BE20: =ROUND(AN20-AW20,2) -> 0 | BF20: =ROUND(AO20-AX20,2) -> 0 | BG20: =SUM(AY20:BF20) -> 18379.64
A21: 19 | B21: =AY20 -> 0 | C21: =AZ20 -> 153.76 | D21: =BA20 -> 5476.85 | E21: =BB20 -> 12749.03 | F21: =BC20 -> 0 | G21: =BD20 -> 0 | H21: =BE20 -> 0 | I21: =BF20 -> 0 | J21: =B21*N('Debt Payoff'!D9)/12 -> 0 | K21: =C21*N('Debt Payoff'!D10)/12 -> 2.5613853 | L21: =D21*N('Debt Payoff'!D11)/12 -> 31.491888 | M21: =E21*N('Debt Payoff'!D12)/12 -> 58.433054 | N21: =F21*N('Debt Payoff'!D13)/12 -> 0 | O21: =G21*N('Debt Payoff'!D14)/12 -> 0 | P21: =H21*N('Debt Payoff'!D15)/12 -> 0 | Q21: =I21*N('Debt Payoff'!D16)/12 -> 0 | R21: =B21+J21 -> 0 | S21: =C21+K21 -> 156.32139 | T21: =D21+L21 -> 5508.3419 | U21: =E21+M21 -> 12807.463 | V21: =F21+N21 -> 0 | W21: =G21+O21 -> 0 | X21: =H21+P21 -> 0 | Y21: =I21+Q21 -> 0 | Z21: =MIN(R21,N('Debt Payoff'!E9)) -> 0 | AA21: =MIN(S21,N('Debt Payoff'!E10)) -> 40 | AB21: =MIN(T21,N('Debt Payoff'!E11)) -> 285 | AC21: =MIN(U21,N('Debt Payoff'!E12)) -> 160 | AD21: =MIN(V21,N('Debt Payoff'!E13)) -> 0 | AE21: =MIN(W21,N('Debt Payoff'!E14)) -> 0 | AF21: =MIN(X21,N('Debt Payoff'!E15)) -> 0 | AG21: =MIN(Y21,N('Debt Payoff'!E16)) -> 0 | AH21: =R21-Z21 -> 0 | AI21: =S21-AA21 -> 116.32139 | AJ21: =T21-AB21 -> 5223.3419 | AK21: =U21-AC21 -> 12647.463 | AL21: =V21-AD21 -> 0 | AM21: =W21-AE21 -> 0 | AN21: =X21-AF21 -> 0 | AO21: =Y21-AG21 -> 0 | AP21: =MAX(0,'Debt Payoff'!$D$17-SUM(Z21:AG21)) -> 320 | AQ21: =MIN(AH21,MAX(0,$AP21-SUMPRODUCT(($AH$1:$AO$1<AH$1)*$AH21:$AO21))) -> 0 | AR21: =MIN(AI21,MAX(0,$AP21-SUMPRODUCT(($AH$1:$AO$1<AI$1)*$AH21:$AO21))) -> 116.32139 | AS21: =MIN(AJ21,MAX(0,$AP21-SUMPRODUCT(($AH$1:$AO$1<AJ$1)*$AH21:$AO21))) -> 203.67861 | AT21: =MIN(AK21,MAX(0,$AP21-SUMPRODUCT(($AH$1:$AO$1<AK$1)*$AH21:$AO21))) -> 0 | AU21: =MIN(AL21,MAX(0,$AP21-SUMPRODUCT(($AH$1:$AO$1<AL$1)*$AH21:$AO21))) -> 0 | AV21: =MIN(AM21,MAX(0,$AP21-SUMPRODUCT(($AH$1:$AO$1<AM$1)*$AH21:$AO21))) -> 0 | AW21: =MIN(AN21,MAX(0,$AP21-SUMPRODUCT(($AH$1:$AO$1<AN$1)*$AH21:$AO21))) -> 0 | AX21: =MIN(AO21,MAX(0,$AP21-SUMPRODUCT(($AH$1:$AO$1<AO$1)*$AH21:$AO21))) -> 0 | AY21: =ROUND(AH21-AQ21,2) -> 0 | AZ21: =ROUND(AI21-AR21,2) -> 0 | BA21: =ROUND(AJ21-AS21,2) -> 5019.66 | BB21: =ROUND(AK21-AT21,2) -> 12647.46 | BC21: =ROUND(AL21-AU21,2) -> 0 | BD21: =ROUND(AM21-AV21,2) -> 0 | BE21: =ROUND(AN21-AW21,2) -> 0 | BF21: =ROUND(AO21-AX21,2) -> 0 | BG21: =SUM(AY21:BF21) -> 17667.12
A22: 20 | B22: =AY21 -> 0 | C22: =AZ21 -> 0 | D22: =BA21 -> 5019.66 | E22: =BB21 -> 12647.46 | F22: =BC21 -> 0 | G22: =BD21 -> 0 | H22: =BE21 -> 0 | I22: =BF21 -> 0 | J22: =B22*N('Debt Payoff'!D9)/12 -> 0 | K22: =C22*N('Debt Payoff'!D10)/12 -> 0 | L22: =D22*N('Debt Payoff'!D11)/12 -> 28.863045 | M22: =E22*N('Debt Payoff'!D12)/12 -> 57.967525 | N22: =F22*N('Debt Payoff'!D13)/12 -> 0 | O22: =G22*N('Debt Payoff'!D14)/12 -> 0 | P22: =H22*N('Debt Payoff'!D15)/12 -> 0 | Q22: =I22*N('Debt Payoff'!D16)/12 -> 0 | R22: =B22+J22 -> 0 | S22: =C22+K22 -> 0 | T22: =D22+L22 -> 5048.523 | U22: =E22+M22 -> 12705.428 | V22: =F22+N22 -> 0 | W22: =G22+O22 -> 0 | X22: =H22+P22 -> 0 | Y22: =I22+Q22 -> 0 | Z22: =MIN(R22,N('Debt Payoff'!E9)) -> 0 | AA22: =MIN(S22,N('Debt Payoff'!E10)) -> 0 | AB22: =MIN(T22,N('Debt Payoff'!E11)) -> 285 | AC22: =MIN(U22,N('Debt Payoff'!E12)) -> 160 | AD22: =MIN(V22,N('Debt Payoff'!E13)) -> 0 | AE22: =MIN(W22,N('Debt Payoff'!E14)) -> 0 | AF22: =MIN(X22,N('Debt Payoff'!E15)) -> 0 | AG22: =MIN(Y22,N('Debt Payoff'!E16)) -> 0 | AH22: =R22-Z22 -> 0 | AI22: =S22-AA22 -> 0 | AJ22: =T22-AB22 -> 4763.523 | AK22: =U22-AC22 -> 12545.428 | AL22: =V22-AD22 -> 0 | AM22: =W22-AE22 -> 0 | AN22: =X22-AF22 -> 0 | AO22: =Y22-AG22 -> 0 | AP22: =MAX(0,'Debt Payoff'!$D$17-SUM(Z22:AG22)) -> 360 | AQ22: =MIN(AH22,MAX(0,$AP22-SUMPRODUCT(($AH$1:$AO$1<AH$1)*$AH22:$AO22))) -> 0 | AR22: =MIN(AI22,MAX(0,$AP22-SUMPRODUCT(($AH$1:$AO$1<AI$1)*$AH22:$AO22))) -> 0 | AS22: =MIN(AJ22,MAX(0,$AP22-SUMPRODUCT(($AH$1:$AO$1<AJ$1)*$AH22:$AO22))) -> 360 | AT22: =MIN(AK22,MAX(0,$AP22-SUMPRODUCT(($AH$1:$AO$1<AK$1)*$AH22:$AO22))) -> 0 | AU22: =MIN(AL22,MAX(0,$AP22-SUMPRODUCT(($AH$1:$AO$1<AL$1)*$AH22:$AO22))) -> 0 | AV22: =MIN(AM22,MAX(0,$AP22-SUMPRODUCT(($AH$1:$AO$1<AM$1)*$AH22:$AO22))) -> 0 | AW22: =MIN(AN22,MAX(0,$AP22-SUMPRODUCT(($AH$1:$AO$1<AN$1)*$AH22:$AO22))) -> 0 | AX22: =MIN(AO22,MAX(0,$AP22-SUMPRODUCT(($AH$1:$AO$1<AO$1)*$AH22:$AO22))) -> 0 | AY22: =ROUND(AH22-AQ22,2) -> 0 | AZ22: =ROUND(AI22-AR22,2) -> 0 | BA22: =ROUND(AJ22-AS22,2) -> 4403.52 | BB22: =ROUND(AK22-AT22,2) -> 12545.43 | BC22: =ROUND(AL22-AU22,2) -> 0 | BD22: =ROUND(AM22-AV22,2) -> 0 | BE22: =ROUND(AN22-AW22,2) -> 0 | BF22: =ROUND(AO22-AX22,2) -> 0 | BG22: =SUM(AY22:BF22) -> 16948.95
A23: 21 | B23: =AY22 -> 0 | C23: =AZ22 -> 0 | D23: =BA22 -> 4403.52 | E23: =BB22 -> 12545.43 | F23: =BC22 -> 0 | G23: =BD22 -> 0 | H23: =BE22 -> 0 | I23: =BF22 -> 0 | J23: =B23*N('Debt Payoff'!D9)/12 -> 0 | K23: =C23*N('Debt Payoff'!D10)/12 -> 0 | L23: =D23*N('Debt Payoff'!D11)/12 -> 25.32024 | M23: =E23*N('Debt Payoff'!D12)/12 -> 57.499887 | N23: =F23*N('Debt Payoff'!D13)/12 -> 0 | O23: =G23*N('Debt Payoff'!D14)/12 -> 0 | P23: =H23*N('Debt Payoff'!D15)/12 -> 0 | Q23: =I23*N('Debt Payoff'!D16)/12 -> 0 | R23: =B23+J23 -> 0 | S23: =C23+K23 -> 0 | T23: =D23+L23 -> 4428.8402 | U23: =E23+M23 -> 12602.93 | V23: =F23+N23 -> 0 | W23: =G23+O23 -> 0 | X23: =H23+P23 -> 0 | Y23: =I23+Q23 -> 0 | Z23: =MIN(R23,N('Debt Payoff'!E9)) -> 0 | AA23: =MIN(S23,N('Debt Payoff'!E10)) -> 0 | AB23: =MIN(T23,N('Debt Payoff'!E11)) -> 285 | AC23: =MIN(U23,N('Debt Payoff'!E12)) -> 160 | AD23: =MIN(V23,N('Debt Payoff'!E13)) -> 0 | AE23: =MIN(W23,N('Debt Payoff'!E14)) -> 0 | AF23: =MIN(X23,N('Debt Payoff'!E15)) -> 0 | AG23: =MIN(Y23,N('Debt Payoff'!E16)) -> 0 | AH23: =R23-Z23 -> 0 | AI23: =S23-AA23 -> 0 | AJ23: =T23-AB23 -> 4143.8402 | AK23: =U23-AC23 -> 12442.93 | AL23: =V23-AD23 -> 0 | AM23: =W23-AE23 -> 0 | AN23: =X23-AF23 -> 0 | AO23: =Y23-AG23 -> 0 | AP23: =MAX(0,'Debt Payoff'!$D$17-SUM(Z23:AG23)) -> 360 | AQ23: =MIN(AH23,MAX(0,$AP23-SUMPRODUCT(($AH$1:$AO$1<AH$1)*$AH23:$AO23))) -> 0 | AR23: =MIN(AI23,MAX(0,$AP23-SUMPRODUCT(($AH$1:$AO$1<AI$1)*$AH23:$AO23))) -> 0 | AS23: =MIN(AJ23,MAX(0,$AP23-SUMPRODUCT(($AH$1:$AO$1<AJ$1)*$AH23:$AO23))) -> 360 | AT23: =MIN(AK23,MAX(0,$AP23-SUMPRODUCT(($AH$1:$AO$1<AK$1)*$AH23:$AO23))) -> 0 | AU23: =MIN(AL23,MAX(0,$AP23-SUMPRODUCT(($AH$1:$AO$1<AL$1)*$AH23:$AO23))) -> 0 | AV23: =MIN(AM23,MAX(0,$AP23-SUMPRODUCT(($AH$1:$AO$1<AM$1)*$AH23:$AO23))) -> 0 | AW23: =MIN(AN23,MAX(0,$AP23-SUMPRODUCT(($AH$1:$AO$1<AN$1)*$AH23:$AO23))) -> 0 | AX23: =MIN(AO23,MAX(0,$AP23-SUMPRODUCT(($AH$1:$AO$1<AO$1)*$AH23:$AO23))) -> 0 | AY23: =ROUND(AH23-AQ23,2) -> 0 | AZ23: =ROUND(AI23-AR23,2) -> 0 | BA23: =ROUND(AJ23-AS23,2) -> 3783.84 | BB23: =ROUND(AK23-AT23,2) -> 12442.93 | BC23: =ROUND(AL23-AU23,2) -> 0 | BD23: =ROUND(AM23-AV23,2) -> 0 | BE23: =ROUND(AN23-AW23,2) -> 0 | BF23: =ROUND(AO23-AX23,2) -> 0 | BG23: =SUM(AY23:BF23) -> 16226.77
A24: 22 | B24: =AY23 -> 0 | C24: =AZ23 -> 0 | D24: =BA23 -> 3783.84 | E24: =BB23 -> 12442.93 | F24: =BC23 -> 0 | G24: =BD23 -> 0 | H24: =BE23 -> 0 | I24: =BF23 -> 0 | J24: =B24*N('Debt Payoff'!D9)/12 -> 0 | K24: =C24*N('Debt Payoff'!D10)/12 -> 0 | L24: =D24*N('Debt Payoff'!D11)/12 -> 21.75708 | M24: =E24*N('Debt Payoff'!D12)/12 -> 57.030096 | N24: =F24*N('Debt Payoff'!D13)/12 -> 0 | O24: =G24*N('Debt Payoff'!D14)/12 -> 0 | P24: =H24*N('Debt Payoff'!D15)/12 -> 0 | Q24: =I24*N('Debt Payoff'!D16)/12 -> 0 | R24: =B24+J24 -> 0 | S24: =C24+K24 -> 0 | T24: =D24+L24 -> 3805.5971 | U24: =E24+M24 -> 12499.96 | V24: =F24+N24 -> 0 | W24: =G24+O24 -> 0 | X24: =H24+P24 -> 0 | Y24: =I24+Q24 -> 0 | Z24: =MIN(R24,N('Debt Payoff'!E9)) -> 0 | AA24: =MIN(S24,N('Debt Payoff'!E10)) -> 0 | AB24: =MIN(T24,N('Debt Payoff'!E11)) -> 285 | AC24: =MIN(U24,N('Debt Payoff'!E12)) -> 160 | AD24: =MIN(V24,N('Debt Payoff'!E13)) -> 0 | AE24: =MIN(W24,N('Debt Payoff'!E14)) -> 0 | AF24: =MIN(X24,N('Debt Payoff'!E15)) -> 0 | AG24: =MIN(Y24,N('Debt Payoff'!E16)) -> 0 | AH24: =R24-Z24 -> 0 | AI24: =S24-AA24 -> 0 | AJ24: =T24-AB24 -> 3520.5971 | AK24: =U24-AC24 -> 12339.96 | AL24: =V24-AD24 -> 0 | AM24: =W24-AE24 -> 0 | AN24: =X24-AF24 -> 0 | AO24: =Y24-AG24 -> 0 | AP24: =MAX(0,'Debt Payoff'!$D$17-SUM(Z24:AG24)) -> 360 | AQ24: =MIN(AH24,MAX(0,$AP24-SUMPRODUCT(($AH$1:$AO$1<AH$1)*$AH24:$AO24))) -> 0 | AR24: =MIN(AI24,MAX(0,$AP24-SUMPRODUCT(($AH$1:$AO$1<AI$1)*$AH24:$AO24))) -> 0 | AS24: =MIN(AJ24,MAX(0,$AP24-SUMPRODUCT(($AH$1:$AO$1<AJ$1)*$AH24:$AO24))) -> 360 | AT24: =MIN(AK24,MAX(0,$AP24-SUMPRODUCT(($AH$1:$AO$1<AK$1)*$AH24:$AO24))) -> 0 | AU24: =MIN(AL24,MAX(0,$AP24-SUMPRODUCT(($AH$1:$AO$1<AL$1)*$AH24:$AO24))) -> 0 | AV24: =MIN(AM24,MAX(0,$AP24-SUMPRODUCT(($AH$1:$AO$1<AM$1)*$AH24:$AO24))) -> 0 | AW24: =MIN(AN24,MAX(0,$AP24-SUMPRODUCT(($AH$1:$AO$1<AN$1)*$AH24:$AO24))) -> 0 | AX24: =MIN(AO24,MAX(0,$AP24-SUMPRODUCT(($AH$1:$AO$1<AO$1)*$AH24:$AO24))) -> 0 | AY24: =ROUND(AH24-AQ24,2) -> 0 | AZ24: =ROUND(AI24-AR24,2) -> 0 | BA24: =ROUND(AJ24-AS24,2) -> 3160.6 | BB24: =ROUND(AK24-AT24,2) -> 12339.96 | BC24: =ROUND(AL24-AU24,2) -> 0 | BD24: =ROUND(AM24-AV24,2) -> 0 | BE24: =ROUND(AN24-AW24,2) -> 0 | BF24: =ROUND(AO24-AX24,2) -> 0 | BG24: =SUM(AY24:BF24) -> 15500.56
